Workbook

Sheet 测算表
B2: 原政策考核
B3: 序号 | C3: 年份 | D3: 月份 | E3: 市场分布 | F3: 队号 | G3: 钻机类型 | H3: 井号 | I3: 区块 | J3: 井别 | K3: 井型 | L3: 开次 | M3: 实际井深（米） | N3: 搬迁周期（天） | O3: 建井周期 | P3: 柴油 | Q3: 机油 | R3: 一般材料 | S3: 设备修理 | T3: 井控材料 | U3: 材料运费 | V3: 生活污水拉运量 | W3: 增效工时 | Y3: 队号 | Z3: 周期兑现（B类） | AA3: 材料预算 | AB3: 小计
B4: 1 | C4: 2025 | D4: 1月 | E4: 大港 | F4: 70520 | G4: ZJ70D | H4: 板111-28 | I4: 板桥 | J4: 开发井 | K4: 定向井 | L4: 2 | M4: 2925 | N4: 7 | O4: 25.5 | P4: 66.117333 | Q4: 1.07 | R4: 68221.627 | S4: 19891.667 | T4: 0 | U4: 1.16 | Y4: 70520 | Z4: =O4*10*120+O4*28*80 -> 87720 | AA4: =P4/2.67*10000+Q4*20000+R4+S4+T4+U4*400+V4*100+W4*50 -> 357607.76 | AB4: =SUM(Z4:AA4) -> 445327.76
B5: 2 | C5: 2025 | D5: 3月 | E5: 大港 | F5: 70520 | G5: ZJ70D | H5: 板172X1 | I5: 板桥 | J5: 开发井 | K5: 定向井 | L5: 2 | M5: 2915 | N5: 5.7916667 | O5: 26 | P5: 71.4725 | Q5: 1.11 | R5: 66804.98 | S5: 18900 | T5: 0 | U5: 60 | V5: 24 | W5: 1.2 | Y5: 70520 | Z5: =O5*10*120+O5*28*80 -> 89440 | AA5: =P5/2.67*10000+Q5*20000+R5+S5+T5+U5*400+V5*100+W5*50 -> 402052.25 | AB5: =SUM(Z5:AA5) -> 491492.25
B6: 3 | C6: 2025 | D6: 4月 | E6: 大港 | F6: 50537 | G6: ZJ50J | H6: 板61-37H | I6: 板桥 | J6: 开发井 | K6: 水平井 | L6: 3 | M6: 2382 | N6: 5.5 | O6: 18.25 | P6: 44.533333 | Q6: 0.48 | R6: 46112.8 | S6: 17233.333 | T6: 0 | U6: 0.92 | V6: 46 | W6: 18.4 | Y6: 50537 | Z6: =O6*10*120+O6*28*80 -> 62780 | AA6: =P6/2.67*10000+Q6*20000+R6+S6+T6+U6*400+V6*100+W6*50 -> 245625.64 | AB6: =SUM(Z6:AA6) -> 308405.64
B7: 4 | C7: 2025 | D7: 5月 | E7: 大港 | F7: 50537 | G7: ZJ50J | H7: 板180X1 | I7: 板桥 | J7: 评价井 | K7: 定向井 | L7: 2 | M7: 3523 | N7: 5.8125 | O7: 26.5 | P7: 76.266667 | Q7: 0.78 | R7: 67987.8 | S7: 28200 | T7: 0 | U7: 78 | V7: 31.2 | W7: 1.56 | Y7: 50537 | Z7: =O7*10*120+O7*28*80 -> 91160 | AA7: =P7/2.67*10000+Q7*20000+R7+S7+T7+U7*400+V7*100+W7*50 -> 431828.75 | AB7: =SUM(Z7:AA7) -> 522988.75
B8: 5 | C8: 2025 | D8: 5月 | E8: 大港 | F8: 50537 | G8: ZJ50J | H8: 板60-47H | I8: 板桥 | J8: 开发井 | K8: 水平井 | L8: 2 | M8: 2314 | N8: 4 | O8: 19.5 | P8: 51.2 | Q8: 0.52 | R8: 37500 | S8: 18800 | T8: 0 | U8: 1 | V8: 50 | W8: 20 | Y8: 50537 | Z8: =O8*10*120+O8*28*80 -> 67080 | AA8: =P8/2.67*10000+Q8*20000+R8+S8+T8+U8*400+V8*100+W8*50 -> 264860.3 | AB8: =SUM(Z8:AA8) -> 331940.3
B9: 6 | C9: 2025 | D9: 5月 | E9: 大港 | F9: 70520 | G9: ZJ70D | H9: 南港13-18 | I9: 唐东 | J9: 开发井 | K9: 定向井 | L9: 3 | M9: 4210 | N9: 6.7916667 | O9: 41.5 | P9: 142.25833 | Q9: 2.16 | R9: 129471.63 | S9: 36750 | T9: 0 | U9: 117 | V9: 46.8 | W9: 2.34 | Y9: 70520 | Z9: =O9*10*120+O9*28*80 -> 142760 | AA9: =P9/2.67*10000+Q9*20000+R9+S9+T9+U9*400+V9*100+W9*50 -> 793821.37 | AB9: =SUM(Z9:AA9) -> 936581.37
B10: 7 | C10: 2025 | D10: 6月 | E10: 大港 | F10: 50537 | G10: ZJ50J | H10: 板61-36H | I10: 板桥 | J10: 开发井 | K10: 水平井 | L10: 2 | M10: 2850 | N10: 4 | O10: 20.5 | P10: 53.783333 | Q10: 0.55 | R10: 40000 | S10: 20053.333 | T10: 0 | U10: 1.06 | V10: 53 | W10: 21.2 | Y10: 50537 | Z10: =O10*10*120+O10*28*80 -> 70520 | AA10: =P10/2.67*10000+Q10*20000+R10+S10+T10+U10*400+V10*100+W10*50 -> 279273.04 | AB10: =SUM(Z10:AA10) -> 349793.04
B11: 8 | C11: 2025 | D11: 7月 | E11: 大港 | F11: 50537 | G11: ZJ50J | H11: 板60-48H | I11: 板桥 | J11: 开发井 | K11: 水平井 | L11: 2 | M11: 2278 | N11: 8.5833333 | O11: 17.5 | P11: 44.1 | Q11: 0.45 | R11: 32500 | S11: 16293.333 | T11: 0 | U11: 0.86 | V11: 43 | W11: 17.2 | Y11: 50537 | Z11: =O11*10*120+O11*28*80 -> 60200 | AA11: =P11/2.67*10000+Q11*20000+R11+S11+T11+U11*400+V11*100+W11*50 -> 228465.87 | AB11: =SUM(Z11:AA11) -> 288665.87
B12: 9 | C12: 2025 | D12: 7月 | E12: 大港 | F12: 70520 | G12: ZJ70D | H12: 唐东9X9 | I12: 唐东 | J12: 评价井 | K12: 定向井 | L12: 3 | M12: 3945 | N12: 5.75 | O12: 31.5 | P12: 90.991667 | Q12: 1.66 | R12: 83333.333 | S12: 26250 | T12: 0 | U12: 83 | V12: 33.2 | W12: 1.66 | Y12: 70520 | Z12: =O12*10*120+O12*28*80 -> 108360 | AA12: =P12/2.67*10000+Q12*20000+R12+S12+T12+U12*400+V12*100+W12*50 -> 520179.09 | AB12: =SUM(Z12:AA12) -> 628539.09
B13: 10 | C13: 2025 | D13: 10月 | E13: 大港 | F13: 70520 | G13: ZJ70D | H13: 唐东20X5 | I13: 唐东 | J13: 评价井 | K13: 定向井 | L13: 3 | M13: 5580 | N13: 16.333333 | O13: 42 | P13: 553612 | Q13: 0.66 | R13: 95000 | S13: 29925 | T13: 0 | U13: 118.33333 | V13: 47.333333 | W13: 2.3666667 | Y13: 70520 | Z13: =O13*10*120+O13*28*80 -> 144480 | AA13: =P13+Q13*20000+R13+S13+T13+U13*400+V13*100+W13*50 -> 743922 | AB13: =SUM(Z13:AA13) -> 888402
AA14: =SUM(AA4:AA13) -> 4267636.1 | AB14: =SUM(AB4:AB13) -> 5192136.1
B16: 新政策考核 | O16: =(P16+Q16)/M27/2 -> 0
B17: 序号 | C17: 年份 | D17: 月份 | E17: 市场分布 | F17: 队号 | G17: 钻机类型 | H17: 井号 | I17: 区块 | J17: 井别 | K17: 井型 | L17: 开次 | M17: 实际井深（米） | N17: 工序 | O17: 米费 | P17: 一般材料 | Q17: 能耗 | R17: 润滑油 | S17: 项修 | T17: 生产水 | U17: 生活污水 | V17: 土工膜 | Y17: 队号 | Z17: 周期兑现 | AA17: 材料预算 | AB17: 小计 | AC17: 总计 | AD17: 增加材料考核项
B18: 1 | C18: 2025 | D18: 1月 | E18: 大港 | F18: 70520 | G18: ZJ70D | H18: 板111-28 | I18: 板桥 | J18: 开发井 | K18: 定向井 | L18: 2 | M18: 2925 | N18: ='[1]05工序定额'!$E$9+'[1]05工序定额'!$E$5+'[1]05工序定额'!$E$13+'[1]05工序定额'!$E$14 -> 0 | O18: ='[1]06米费定额 '!$E$5*M18*38 -> 47607.076 | P18: ='[1]07一般材料定额'!$F$5*M18 -> 62056.826 | Q18: ='[1]08能耗定额'!$G$5*M18 -> 286679.25 | R18: =M18*'[1]09润滑油定额 '!$E$5*'[1]14钻机挂钩系数'!$D$7 -> 21045.69 | S18: =M18*'[1]10项修定额'!$E$5*'[1]14钻机挂钩系数'!$E$7 -> 10951.205 | T18: =M18*'[1]11生产水定额'!$E$5 -> 13460.312 | U18: ='[1]12生活污水定额'!$E$5*M18 -> 7300.803 | V18: ='[1]13土工膜定额'!$G$6 -> 12546 | Y18: 70520 | Z18: =N18+O18 -> 47607.076 | AA18: =P18+Q18+R18+S18 -> 380732.97 | AB18: =Z18+AA18 -> 428340.05 | AC18: =Z18+AD18+AA18 -> 461647.16 | AD18: =T18+U18+V18 -> 33307.115
B19: 2 | C19: 2025 | D19: 3月 | E19: 大港 | F19: 70520 | G19: ZJ70D | H19: 板172X1 | I19: 板桥 | J19: 开发井 | K19: 定向井 | L19: 2 | M19: 2915 | N19: ='[1]05工序定额'!$E$9+'[1]05工序定额'!$E$5+'[1]05工序定额'!$E$13+'[1]05工序定额'!$E$14 -> 0 | O19: ='[1]06米费定额 '!$E$5*M19*38 -> 47444.317 | P19: ='[1]07一般材料定额'!$F$5*M19 -> 61844.666 | Q19: ='[1]08能耗定额'!$G$5*M19 -> 285699.15 | R19: =M19*'[1]09润滑油定额 '!$E$5*'[1]14钻机挂钩系数'!$D$7 -> 20973.739 | S19: =M19*'[1]10项修定额'!$E$5*'[1]14钻机挂钩系数'!$E$7 -> 10913.765 | T19: =M19*'[1]11生产水定额'!$E$5 -> 13414.293 | U19: ='[1]12生活污水定额'!$E$5*M19 -> 7275.843 | V19: ='[1]13土工膜定额'!$G$6 -> 12546 | Y19: 70520 | Z19: =N19+O19 -> 47444.317 | AA19: =P19+Q19+R19+S19 -> 379431.32 | AB19: =Z19+AA19 -> 426875.64 | AC19: =Z19+AD19+AA19 -> 460111.77 | AD19: =T19+U19+V19 -> 33236.136
B20: 3 | C20: 2025 | D20: 4月 | E20: 大港 | F20: 50537 | G20: ZJ50J | H20: 板61-37H | I20: 板桥 | J20: 开发井 | K20: 水平井 | L20: 3 | M20: 2382 | N20: ='[1]05工序定额'!$E$5+'[1]05工序定额'!$E$8+'[1]05工序定额'!$E$13 -> #VALUE! | O20: =M20*'[1]06米费定额 '!$E$33*38 -> 34687.033 | P20: =M20*'[1]07一般材料定额'!$E$33 -> 39895.833 | Q20: =M20*'[1]08能耗定额'!$G$25 -> 239581.56 | R20: ='[1]09润滑油定额 '!$E$33*M20*'[1]14钻机挂钩系数'!$D$5 -> 7682.3323 | S20: =M20*'[1]10项修定额'!$E$33*'[1]14钻机挂钩系数'!$E$5 -> 7181.25 | T20: =M20*'[1]11生产水定额'!$E$33 -> 10169.057 | U20: =M20*'[1]12生活污水定额'!$E$33 -> 5319.4444 | V20: ='[1]13土工膜定额'!$G$5 -> 11500.5 | Y20: 50537 | Z20: =N20+O20 -> #VALUE! | AA20: =P20+Q20+R20+S20 -> 294340.98 | AB20: =Z20+AA20 -> #VALUE! | AC20: =Z20+AD20+AA20 -> #VALUE! | AD20: =T20+U20+V20 -> 26989.002
B21: 4 | C21: 2025 | D21: 5月 | E21: 大港 | F21: 50537 | G21: ZJ50J | H21: 板180X1 | I21: 板桥 | J21: 评价井 | K21: 定向井 | L21: 2 | M21: 3523 | N21: ='[1]05工序定额'!$E$5+'[1]05工序定额'!$E$8+'[1]05工序定额'!$E$13 -> #VALUE! | O21: ='[1]06米费定额 '!$E$5*M21*38 -> 57340.079 | P21: ='[1]07一般材料定额'!$F$5*M21 -> 74743.999 | Q21: ='[1]08能耗定额'!$G$5*M21 -> 345289.23 | R21: =M21*'[1]09润滑油定额 '!$E$5*'[1]14钻机挂钩系数'!$D$5 -> 12699.43 | S21: =M21*'[1]10项修定额'!$E$5*'[1]14钻机挂钩系数'!$E$5 -> 11871.106 | T21: =M21*'[1]11生产水定额'!$E$5 -> 16212.198 | U21: ='[1]12生活污水定额'!$E$5*M21 -> 8793.4117 | V21: ='[1]13土工膜定额'!$G$5 -> 11500.5 | Y21: 50537 | Z21: =N21+O21 -> #VALUE! | AA21: =P21+Q21+R21+S21 -> 444603.76 | AB21: =Z21+AA21 -> #VALUE! | AC21: =Z21+AD21+AA21 -> #VALUE! | AD21: =T21+U21+V21 -> 36506.109
B22: 5 | C22: 2025 | D22: 5月 | E22: 大港 | F22: 50537 | G22: ZJ50J | H22: 板60-47H | I22: 板桥 | J22: 开发井 | K22: 水平井 | L22: 2 | M22: 2314 | N22: ='[1]05工序定额'!$E$5+'[1]05工序定额'!$E$8+'[1]05工序定额'!$E$13 -> #VALUE! | O22: =M22*38*'[1]06米费定额 '!$E$20 -> 30773.427 | P22: =M22*'[1]07一般材料定额'!$E$20 -> 35394.538 | Q22: =M22*'[1]08能耗定额'!$G$20 -> 189053.8 | R22: =M22*'[1]09润滑油定额 '!$E$20*'[1]14钻机挂钩系数'!$D$5 -> 6815.5639 | S22: =M22*'[1]10项修定额'!$E$20*'[1]14钻机挂钩系数'!$E$5 -> 6371.0168 | T22: =M22*'[1]11生产水定额'!$E$20 -> 10648.501 | U22: =M22*'[1]12生活污水定额'!$E$20 -> 4719.2717 | V22: ='[1]13土工膜定额'!$G$5 -> 11500.5 | Y22: 50537 | Z22: =N22+O22 -> #VALUE! | AA22: =P22+Q22+R22+S22 -> 237634.92 | AB22: =Z22+AA22 -> #VALUE! | AC22: =Z22+AD22+AA22 -> #VALUE! | AD22: =T22+U22+V22 -> 26868.273
B23: 6 | C23: 2025 | D23: 5月 | E23: 大港 | F23: 70520 | G23: ZJ70D | H23: 南港13-18 | I23: 唐东 | J23: 开发井 | K23: 定向井 | L23: 3 | M23: 4210 | N23: ='[1]05工序定额'!$E$9+'[1]05工序定额'!$E$5+'[1]05工序定额'!$E$13+'[1]05工序定额'!$E$14 -> 0 | O23: =M23*38*'[1]06米费定额 '!$E$31 -> 71738.09 | P23: =M23*'[1]07一般材料定额'!$F$31 -> 93512.109 | Q23: =M23*'[1]08能耗定额'!$G$31 -> 567802.7 | R23: =M23*'[1]09润滑油定额 '!$E$31*'[1]14钻机挂钩系数'!$E$7 -> 34654.488 | S23: =M23*'[1]10项修定额'!$E$31*'[1]14钻机挂钩系数'!$E$7 -> 16502.137 | T23: =M23*'[1]11生产水定额'!$E$31 -> 23301.793 | U23: =M23*'[1]12生活污水定额'!$E$31 -> 11001.425 | V23: ='[1]13土工膜定额'!$G$6 -> 12546 | Y23: 70520 | Z23: =N23+O23 -> 71738.09 | AA23: =P23+Q23+R23+S23 -> 712471.43 | AB23: =Z23+AA23 -> 784209.52 | AC23: =Z23+AD23+AA23 -> 831058.74 | AD23: =T23+U23+V23 -> 46849.218
B24: 7 | C24: 2025 | D24: 6月 | E24: 大港 | F24: 50537 | G24: ZJ50J | H24: 板61-36H | I24: 板桥 | J24: 开发井 | K24: 水平井 | L24: 2 | M24: 2850 | N24: ='[1]05工序定额'!$E$9+'[1]05工序定额'!$E$5+'[1]05工序定额'!$E$13+'[1]05工序定额'!$E$14 -> 0 | O24: =M24*38*'[1]06米费定额 '!$E$20 -> 37901.584 | P24: =M24*'[1]07一般材料定额'!$E$20 -> 43593.1 | Q24: =M24*'[1]08能耗定额'!$G$20 -> 232845 | R24: =M24*'[1]09润滑油定额 '!$E$20*'[1]14钻机挂钩系数'!$D$5 -> 8394.277 | S24: =M24*'[1]10项修定额'!$E$20*'[1]14钻机挂钩系数'!$E$5 -> 7846.7579 | T24: =M24*'[1]11生产水定额'!$E$20 -> 13115.051 | U24: =M24*'[1]12生活污水定额'!$E$20 -> 5812.4133 | V24: ='[1]13土工膜定额'!$G$5 -> 11500.5 | Y24: 50537 | Z24: =N24+O24 -> 37901.584 | AA24: =P24+Q24+R24+S24 -> 292679.13 | AB24: =Z24+AA24 -> 330580.72 | AC24: =Z24+AD24+AA24 -> 361008.68 | AD24: =T24+U24+V24 -> 30427.965
B25: 8 | C25: 2025 | D25: 7月 | E25: 大港 | F25: 50537 | G25: ZJ50J | H25: 板60-48H | I25: 板桥 | J25: 开发井 | K25: 水平井 | L25: 2 | M25: 2278 | N25: ='[1]05工序定额'!$E$5+'[1]05工序定额'!$E$8+'[1]05工序定额'!$E$13 -> #VALUE! | O25: =M25*38*'[1]06米费定额 '!$E$20 -> 30294.67 | P25: =M25*'[1]07一般材料定额'!$E$20 -> 34843.888 | Q25: =M25*'[1]08能耗定额'!$G$20 -> 186112.6 | R25: =M25*'[1]09润滑油定额 '!$E$20*'[1]14钻机挂钩系数'!$D$5 -> 6709.5309 | S25: =M25*'[1]10项修定额'!$E$20*'[1]14钻机挂钩系数'!$E$5 -> 6271.8998 | T25: =M25*'[1]11生产水定额'!$E$20 -> 10482.838 | U25: =M25*'[1]12生活污水定额'!$E$20 -> 4645.8517 | V25: ='[1]13土工膜定额'!$G$5 -> 11500.5 | Y25: 50537 | Z25: =N25+O25 -> #VALUE! | AA25: =P25+Q25+R25+S25 -> 233937.92 | AB25: =Z25+AA25 -> #VALUE! | AC25: =Z25+AD25+AA25 -> #VALUE! | AD25: =T25+U25+V25 -> 26629.189
B26: 9 | C26: 2025 | D26: 7月 | E26: 大港 | F26: 70520 | G26: ZJ70D | H26: 唐东9X9 | I26: 唐东 | J26: 评价井 | K26: 定向井 | L26: 3 | M26: 3945 | N26: ='[1]05工序定额'!$E$9+'[1]05工序定额'!$E$5+'[1]05工序定额'!$E$13+'[1]05工序定额'!$E$14 -> 0 | O26: =M26*38*'[1]06米费定额 '!$E$31 -> 67222.509 | P26: =M26*'[1]07一般材料定额'!$F$31 -> 87625.955 | Q26: =M26*'[1]08能耗定额'!$G$31 -> 532062.15 | R26: =M26*'[1]09润滑油定额 '!$E$31*'[1]14钻机挂钩系数'!$E$7 -> 32473.148 | S26: =M26*'[1]10项修定额'!$E$31*'[1]14钻机挂钩系数'!$E$7 -> 15463.404 | T26: =M26*'[1]11生产水定额'!$E$31 -> 21835.053 | U26: =M26*'[1]12生活污水定额'!$E$31 -> 10308.936 | V26: ='[1]13土工膜定额'!$G$6 -> 12546 | Y26: 70520 | Z26: =N26+O26 -> 67222.509 | AA26: =P26+Q26+R26+S26 -> 667624.66 | AB26: =Z26+AA26 -> 734847.17 | AC26: =Z26+AD26+AA26 -> 779537.16 | AD26: =T26+U26+V26 -> 44689.989
B27: 10 | C27: 2025 | D27: 10月 | E27: 大港 | F27: 70520 | G27: ZJ70D | H27: 唐东20X5 | I27: 唐东 | J27: 评价井 | K27: 定向井 | L27: 3 | M27: 5580 | N27: ='[1]05工序定额'!$E$9+'[1]05工序定额'!$E$5+'[1]05工序定额'!$E$13+'[1]05工序定额'!$E$14 -> 0 | O27: =M27*38*'[1]06米费定额 '!$E$31 -> 95082.789 | P27: =M27*'[1]07一般材料定额'!$F$31 -> 123942.42 | Q27: =M27*'[1]08能耗定额'!$G$31 -> 752574.6 | R27: =M27*'[1]09润滑油定额 '!$E$31*'[1]14钻机挂钩系数'!$E$7 -> 45931.601 | S27: =M27*'[1]10项修定额'!$E$31*'[1]14钻机挂钩系数'!$E$7 -> 21872.191 | T27: =M27*'[1]11生产水定额'!$E$31 -> 30884.562 | U27: =M27*'[1]12生活污水定额'!$E$31 -> 14581.461 | V27: ='[1]13土工膜定额'!$G$6 -> 12546 | Y27: 70520 | Z27: =N27+O27 -> 95082.789 | AA27: =P27+Q27+R27+S27 -> 944320.81 | AB27: =Z27+AA27 -> 1039403.6 | AC27: =Z27+AD27+AA27 -> 1097415.6 | AD27: =T27+U27+V27 -> 58012.022
AA28: =SUM(AA18:AA27) -> 4587777.9 | AD28: =SUM(AD18:AD27) -> 363515.02 | AH28: =(AD28+AA28-AA14)/AA14 -> 0.16019568
Y30: 与原政策对比
H31: 张海31-43 | Q31: =4318*'[1]08能耗定额'!$G$26 -> 625721.38 | Y31: 队号 | Z31: 周期兑现差额 | AA31: 材料考核项差额 | AB31: 总体考核差额
Y32: 70520 | Z32: =Z18-Z4 -> -40112.924 | AA32: =AA18+AD18-AA4 -> 56432.33 | AB32: =AC18-AB4 -> 16319.406
Y33: 70520 | Z33: =Z19-Z5 -> -41995.683 | AA33: =AA19+AD19-AA5 -> 10615.21 | AB33: =AC19-AB5 -> -31380.473
Y34: 50537 | Z34: =Z20-Z6 -> #VALUE! | AA34: =AA20+AD20-AA6 -> 75704.333 | AB34: =AC20-AB6 -> #VALUE!
Y35: 50537 | Z35: =Z21-Z7 -> #VALUE! | AA35: =AA21+AD21-AA7 -> 49281.127 | AB35: =AC21-AB7 -> #VALUE!
Y36: 50537 | Z36: =Z22-Z8 -> #VALUE! | AA36: =AA22+AD22-AA8 -> -357.10823 | AB36: =AC22-AB8 -> #VALUE!
Y37: 70520 | Z37: =Z23-Z9 -> -71021.91 | AA37: =AA23+AD23-AA9 -> -34500.722 | AB37: =AC23-AB9 -> -105522.63
Y38: 50537 | Z38: =Z24-Z10 -> -32618.416 | AA38: =AA24+AD24-AA10 -> 43834.06 | AB38: =AC24-AB10 -> 11215.645
Y39: 50537 | Z39: =Z25-Z11 -> #VALUE! | AA39: =AA25+AD25-AA11 -> 32101.235 | AB39: =AC25-AB11 -> #VALUE!
Y40: 70520 | Z40: =Z26-Z12 -> -41137.491 | AA40: =AA26+AD26-AA12 -> 192135.55 | AB40: =AC26-AB12 -> 150998.06
Y41: 70520 | Z41: =Z27-Z13 -> -49397.211 | AA41: =AA27+AD27-AA13 -> 258410.83 | AB41: =AC27-AB13 -> 209013.62
Y45: 全年差额
Y46: 70520 | Z46: =Z32+Z33+Z37+Z40+Z41 -> -243665.22 | AA46: =AA32+AA33+AA37+AA40+AA41 -> 483093.2 | AB46: =AB32+AB33+AB37+AB40+AB41 -> 239427.98
...

Sheet 目录
A1: 附件1
A3: 目录
A4: 序号 | B4: 名称
A5: 1 | B5: 奖金系数表
A6: 2 | B6: 人员定额
A7: 3 | B7: 机关部门、直属单位通用管理指标考核表
A8: 4 | B8: 机关部门、直属单位专业管理指标考核表
A9: 5 | B9: 大港油区工序定额
A10: 6 | B10: 大港油区米费定额
A11: 7 | B11: 大港油区一般材料定额
A12: 8 | B12: 大港油区能耗定额
A13: 9 | B13: 大港油区润滑油定额
A14: 10 | B14: 大港油区项修定额
A15: 11 | B15: 大港油区生产水定额
A16: 12 | B16: 大港油区生活污水定额
... A21: 17 | B21: 事故复杂率指标

Sheet 1奖金系数表
A1: 附件1-1
A3: 切块奖金系数表
A4: 部门或单位 | B4: 岗位名称 | C4: 系数
A5: 机关直属 | B5: 室内管理岗 | C5: 1.1
B6: 现场管理岗 | C6: 1.2
B7: 盯井工程师 | C7: 2 | D7: 凌云按盯井工程师系数2.0造
A8: 安全监督中心 | B8: 油区现场监督 | C8: 1.3
B9: 外部、外包现场监督 | C9: 1.5
A10: 生产保障中心 | B10: 档案管理 | C10: 1.1
B11: 班长、电工、司机、调度、安全员 | C11: 0.9
B12: 办事员、会务、打字员、食堂 | C12: 0.75
B13: 门岗 | C13: 0.65
B14: 清洁班、护厂、活动中心 | C14: 0.6
B15: 技术员、班长 | C15: 1
B16: 搬迁工、修理工、安全员 | C16: 0.9
B17: 办事员 | C17: 0.75
A18: 物资管理中心 | B18: 班长 | C18: 1
B19: 押运员、送料员、稽核员、安全员 | C19: 0.9
B20: 保管员 | C20: 0.8
A21: 外部项目部 | B21: 项目部管理人员 | C21: 1.6 | D21: 周雪峰、刘金文的系数1.4是否改，南部机构撤销
A22: 国际项目部/新项目管理部 | B22: 新项目部管理人员 | C22: 1.4 | D22: 2.13日修改为1.6系数
A23: 钻井队 | B23: 大港油区钻井队 | C23: 2.2
B24: 外部市场钻井队 | C24: 2.5
A25: 注：项目部驻公司机关办公人员奖金系数参照机关直属标准执行。
A27: 钻井队管理岗位奖金系数表
A28: 部门或单位 | B28: 岗位名称 | C28: 系数
A29: 钻井队 | B29: 队长（平台经理） | C29: 1.6
B30: 党支部书记、第一技术员 | C30: 1.4
B31: 副队长、第二技术员、司钻 | C31: 1.2
B32: 实习技术员 | C32: 0.9
A33: 注：该系数为指导性系数。司钻、实习技术员参照管理岗设置奖金系数。
A35: 钻井队操作岗位奖金系数表
A36: 部门或单位 | B36: 岗位名称 | C36: 系数
A37: 钻井队 | B37: 司钻 | C37: 1.5
B38: 机房大班、钻台大班、电气师、副司钻 | C38: 1.3
B39: 钻工、泥浆工、司机 | C39: 1.2
B40: 机工、发电工、炊事员、成本员、材料员、管理员 | C40: 1.1
A41: 注：该系数为指导性系数。

Sheet 2人员定额
A1: 附件1-2
A3: 人员定额
A4: 序号 | B4: 主体单位 | C4: 所属地区 | D4: 钻井队定员（人/队） | E4: 项目部定编（人）
A6: 1 | B6: 大港油区项目 | C6: 天津、河北等 | D6: 38 | E6: /
A7: 2 | B7: 西北项目 | C7: 南疆 | D7: 44 | E7: 88
C8: 北疆 | D8: 38
A9: 3 | B9: 长庆项目 | C9: 陕西、甘肃、内蒙等 | D9: 38 | E9: 73
A10: 注：动力外包、食堂外包队伍减少定员3人/队。

Sheet 3机关部门、直属单位通用管理指标考核表
A1: 附件1-3
A3: 机关部门、直属单位通用管理指标考核表
A4: 序号 | B4: 单位 | C4: 人数 | D4: 办公费（元/年） | E4: 车辆使用(台班/年) | F4: 备注
A5: 1 | B5: 办公室/党委办公室 | C5: 9 | D5: 3300 | E5: 31 | F5: 直属管理岗4人
A6: 2 | B6: 市场与生产协调部 | C6: 23 | D6: 7400 | E6: 911 | F6: 室内3人、室外8人
A7: 3 | B7: 工程技术部 | C7: 17 | D7: 5200 | E7: 444 | F7: 直属管理岗6人、EISC岗5人
A8: 4 | B8: 质量安全环保部 | C8: 21 | D8: 6190 | E8: 600 | F8: 室外5人、视频监控3人、门卫3人
A9: 5 | B9: 装备管理部 | C9: 9 | D9: 3300 | E9: 741 | F9: 室外3人
A10: 6 | B10: 人力资源部/党委组织部 | C10: 12 | D10: 6000 | E10: 107 | F10: 含人力资源共享中心6人
A11: 7 | B11: 企划财务部 | C11: 20 | D11: 10000 | E11: 82
A12: 8 | B12: 党群工作部/纪委办公室 | C12: 15 | D12: 6560 | E12: 134 | F12: 门卫2人
A13: 9 | B13: 物资管理中心 | C13: 26 | D13: 3820 | E13: 317 | F13: 管理岗9人、长期室内13人、押运4人
A14: 10 | B14: 安全监督中心 | C14: 22 | D14: 2570 | E14: 286 | F14: 管理岗4人、监督18人
A15: 11 | B15: 井控监督中心 | C15: 6 | D15: 1800 | E15: 0 | F15: 用车与工程技术科合并考核
A16: 12 | B16: 数智中心 | C16: 5 | D16: 2500 | E16: 20
A17: 13 | B17: 生产保障中心 | C17: 112 | D17: 75700 | E17: 335 | F17: 管理岗6人、室内6人，含公共实施消耗7万元
A18: 合 计 | C18: =SUM(C5:C17) -> 297 | D18: =SUM(D5:D17) -> 134340 | E18: =SUM(E5:E17) -> 4008
A19: 备注： 1．车辆使用每节余（超支）1台班奖励（扣减）科室80元；办公费按照节余（超支）额的50%进行奖励（扣减）。 2．机关部门使用车辆按台班签字；当日使用车辆8小时及以上，按1台班计算。多部门拼车出行，该车辆使用时间由用车部门分摊，计入考核指标。 3．办公费指标核定标准：机关部门人员核定标准为500元/人，长期室外工作人员100元/人；直属单位管理岗200元/人，办事员及长期室内工作人员100元/人，其他岗位人员按30元/人，安全监督65元/人。

Sheet 4机关部门、直属单位专业管理指标考核细则
A1: 附件1-4
A3: 机关部门、直属单位专业管理指标考核表
A4: 部门(单位) | B4: 承包管理指标项目名称 | C4: 计量单位 | D4: 承包管理指标 | E4: 考核方式 | F4: 考核办法
A6: 通用指标 | B6: 部门原因造成钻井队施工异常 | C6: 次 | D6: 0 | E6: 季度 | F6: 季度考核，每发生一次，核减责任部门10%月奖。
B7: 渤海钻探公司及相关处室下达的考核指标 | C7: 项 | D7: 0 | E7: 月度 | F7: 对公司相关职责承担部门（单位）进行考核，进度未完成核减业务牵头部门（单位）20%月奖、业务配合部门（单位）10%月奖；年度未完成考核指标累计核减业务牵头部门(单位）月度100%月奖、业务配合部门（单位）月度50%月奖。
B8: 生产经营过程管理考核 | E8: 月度 | F8: 在各级检查、审核中发现专业路管理问题或单位履职未尽责造成上级通报批评影响公司声誉的，每起核减责任单位10%月奖。
B9: 预提费用考核 | C9: % | E9: 月度 | F9: 考核变动成本月度预提费用准确性，考核结果与业务经办部门（含项目部)及机关归口部门负责人挂钩，费用偏差≤5%合格，5%＜费用偏差≤10%，沉没月奖10%；10%＜费用偏差≤15%，沉没月奖20%；费用偏差＞15%，沉没月奖30%。
B10: 荣誉奖励 | E10: 季度 | F10: 获得国家级、省部级集体荣誉，核增获奖集体人均绩效薪酬不超过1200元、800元，生产类核增加倍。上级有核增绩效薪酬的不重复。
A11: 市场与生产协调部 | B11: 大港油区搬安周期考核 | C11: % | E11: 季度 | F11: 按季度完成井进行考核，实际平均口井搬安天数同比去年缩短10%，核增绩效薪酬15000元；同比缩短15%，核增绩效薪酬20000元；超过去年平均口井搬安天数，核减10000元。
B12: 网电接入口井数和接入及时率 | C12: 次 | E12: 口井 | F12: 新搬迁井位的钻井队，在开钻前接入并使用网电的，口井核增绩效薪酬2000元。二开前完成核增绩效薪酬1000元。
B13: 公司进尺任务 | C13: 万米 | E13: 月度 | F13: 月度完成核增绩效薪酬5000元，未完成核减绩效薪酬2500元。
B14: 大港油区进尺任务 | C14: 万米 | E14: 月度 | F14: 月度完成核增绩效薪酬10000元，未完成核减绩效薪酬10000元。每增加（减少）1米，核增（核减）绩效薪酬1元。
B15: 公司创收任务 | C15: 亿元 | E15: 季度/年度 | F15: 季度完成核增绩效薪酬10000元，未完成核减绩效薪酬5000元；全年完成核增绩效薪酬20000元，未完成核减绩效薪酬10000元。
B16: 大港油区创收任务 | C16: 亿元 | E16: 季度/年度 | F16: 季度完成核增绩效薪酬20000元，未完成核减绩效薪酬20000元；年度完成核增绩效薪酬20000元，未完成核减绩效薪酬20000元。年度超额完成指标占比每1%核增绩效薪酬30000元。未达标准每1%核减绩效薪酬30000元。
A17: 工程技术部、井控监督中心 | B17: 公司整体提速（钻完井周期） | C17: % | E17: 半年/年度 | F17: 半年完成核增绩效薪酬20000元，未完成核减绩效薪酬10000元；全年完成核增绩效薪酬30000元；全年未完成核减绩效薪酬15000元。
B18: 大港油区五类井提速（钻井周期） | C18: % | E18: 季度/年度 | F18: 季度完成核增绩效薪酬20000元，未完成核减绩效薪酬10000元；年度完成核增绩效薪酬30000元，未完成核减绩效薪酬15000元。
B19: 大港油区提速工具考核 | C19: 天 | E19: 口井 | F19: 每口井考核提速工具提速目标，达到预期目标核增绩效薪酬3000元，未达到核减绩效薪酬1500元。
B20: 公司事故复杂考核 | C20: % | E20: 半年/年度 | F20: 半年完成核增绩效薪酬20000元，未完成核减绩效薪酬10000元；全年完成任务核增绩效薪酬40000元，未完成核减绩效薪酬20000元。
B21: 大港油区事故复杂考核 | C21: % | E21: 季度/年度 | F21: 季度完成核增绩效薪酬20000元，未完成核减绩效薪酬10000元；第四季度按年度考核，完成任务核增绩效薪酬40000元，未完成核减绩效薪酬20000元。
B22: 大港油区钻头米费考核 | C22: 元/米 | D22: 2025年平均值 | E22: 季度 | F22: 季度完成核增绩效薪酬10000元，未完成核减绩效薪酬5000元。钻头米费标准与平均井深同比例增减。
B23: 施工质量控制 | E23: 月度/年度 | F23: 发生井口未正常交井事件每起核减绩效薪酬3000元。年度固井质量优质率高于同市场水平核增绩效薪酬30000元。低于平均值核减绩效薪酬15000元。
A24: 质量安全环保部 | B24: 公司安全事故 | C24: 起 | D24: 0 | E24: 月度 | F24: 一般C级及以上安全事故，每发生1起核减10%绩效薪酬，部门负责人加倍。
B25: “四不两直”及体系审核 | E25: 季度 | F25: 在上级“四不两直”或体系审核中得到上级通报表扬的每次核增绩效薪酬20000元，发生严重违反上级禁令造成恶劣影响的，每次核减绩效薪酬10000元。
B26: 质量控制 | E26: 月度 | F26: 完成上级下达的质量工作目标。每发生一起质量事件核减绩效薪酬3000元。
B27: 年度HSE指标完成情况 | E27: 年度 | F27: 全年完成HSE指标，现场人员收入不低于市场、生产、装备现场管理人员平均收入水平。
A28: 装备管理部 | B28: 网电接入口井数和接入及时率 | C28: 次 | E28: 口井 | F28: 新搬迁井位的钻井队，在开钻前接入并使用网电的，口井核增绩效薪酬2000元。二开前完成核增绩效薪酬1000元。
B29: 机修率 | C29: % | D29: 0.8 | E29: 季度 | F29: 按当月施工井时效进行统计，机修率每低于考核指标0.1个点，核增绩效薪酬500元，每超出0.1点，核减绩效薪酬500元。考核结果与钻机利用率挂钩：钻机利用率≥80%，按全额考核兑现；当钻机利用率＜80%，按考核金额×（实际钻机利用率÷0.8)兑现。
B30: 大港油区设备保障 | C30: 次 | D30: 3 | E30: 季度 | F30: 生产过程中发生设备影响生产的情况每超出一起核减绩效薪酬1000元；在各类检查中发现设备不能正常运转而影响生产核减绩效薪酬2000元/起；发生因设备原因造成的事故复杂核减绩效薪酬10000元；季度未发生核增绩效薪酬10000元。
A31: 物资管理中心 | B31: 完成井一般材料消耗节余 | C31: % | D31: 1.5 | E31: 季度 | F31: 与单井一般材料定额相比，节余1.5%以上，按超额节余金额的2%核增绩效薪酬，节余不足部分按照2%核减绩效薪酬。
B32: 现场物资质量管控 | C32: 起 | D32: 0 | E32: 季度 | F32: 因物资质量问题影响生产，每发生1起核减绩效薪酬1000元。
B33: 物资运费 | C33: 车次/台月 | D33: 2 | E33: 季度 | F33: 每节约1车次核增绩效薪酬400元,增加1车次核减绩效薪酬200元。
A34: 生产保障中心 | B34: 单井电料消耗 | C34: 元 | D34: 4000 | E34: 季度 | F34: 按照季度完成井节超额10%核增（核减）绩效薪酬。
B35: 修理加工产值 | C35: 万元 | D35: 415 | E35: 季度 | F35: 按超（差）额5%核增（核减）绩效薪酬。设备修理、加工按市场价计算产值。
B36: 部门用车情况 | C36: 台班 | D36: 各部门 | E36: 年度 | F36: 根据各单位考核结果，完成考核指标核增绩效薪酬总额20%进行核增，未完成考核指标核减绩效薪酬总额20%进行核减。
B37: 增效工时考核 | C37: 天/人 | D37: 50 | E37: 季度 | F37: 鼓励搬迁队、水电队主动支援一线工作，按工时超（差）额进行核增（核减）绩效薪酬100元/天。

Sheet 5工序定额
A1: 附件1-5
A3: 大港油区工序定额
A4: 序号 | B4: 工序 | C4: 单位 | D4: 定额 | E4: 备注
A5: 1 | B5: 搬迁拆卸 | C5: 元/井次 | D5: 7245.3333
A6: 2 | B6: 平移拆卸 | C6: 元/井次 | D6: 1811.3333
A7: 3 | B7: 搬迁转场(腾井场） | C7: 元/井次 | D7: 3622.6667
A8: 4 | B8: 搬安（50型） | C8: 元/井次 | D8: 16302 | E8: 冬季上浮20%
A9: 5 | B9: 搬安（70型） | C9: 元/井次 | D9: 21736 | E9: 冬季上浮20%
A10: 6 | B10: 平移 | C10: 元/井次 | D10: 3622.6667
A11: 7 | B11: 砌方井 | C11: 元/井次 | D11: 1811.3333
A12: 8 | B12: 摆基础 | C12: 元/井次 | D12: 1811.3333
A13: 9 | B13: 配合安装泥浆不落地 | C13: 元/井次 | D13: 1811.3333
A14: 10 | B14: 顶驱拆装 | C14: 元/井次 | D14: 5434
A15: 11 | B15: 机械手拆装 | C15: 元/井次 | D15: 5434
A16: 12 | B16: 冬防保温（自保温） | C16: 元/井次 | D16: 3622.6667
A17: 13 | B17: 油基泥浆施工 | C17: 元/台月 | D17: 6000
A18: 14 | B18: 设备配套 | C18: 元/天·人 | D18: 104.86667

Sheet 大港油区定额统计
A1: 大港油区定额测算基础数据
A3: 序号 | B3: 井型 | C3: 区块 | D3: 开次 | E3: 累计进尺 | F3: 定员人数 | G3: 累计钻完井周期 | H3: 累计米费兑现 | I3: 一般材料累计 | J3: 能耗累计 | K3: 润滑油累计 | L3: 项修累计 | M3: 生产水累计 | N3: 生活污水累计 | O3: 累计贡献毛益额 | P3: 累计收入
A4: =ROW()-3 -> 1 | B4: 定向井 | C4: 板桥（＜2500米） | D4: 2 | E4: =SUMIFS(转置表!O:O,转置表!L:L,B4,转置表!J:J,C4,转置表!M:M,D4) -> 3957 | F4: 38 | G4: =SUMIFS(转置表!T:T,转置表!L:L,B4,转置表!J:J,C4,转置表!M:M,D4) -> 25 | H4: 54340 | I4: 56666.667 | J4: 323056.18 | K4: 17500 | L4: 8333.3333 | M4: 0 | N4: 8333.3333
A5: =ROW()-3 -> 2 | B5: 定向井 | C5: 板桥（＜3500米） | D5: 2 | E5: =SUMIFS(转置表!O:O,转置表!L:L,B5,转置表!J:J,C5,转置表!M:M,D5) -> 44234 | F5: 38 | G5: =SUMIFS(转置表!T:T,转置表!L:L,B5,转置表!J:J,C5,转置表!M:M,D5) -> 264.85417 | H5: 575687.02 | I5: 600336.11 | J5: 3279717.3 | K5: 185397.92 | L5: 88284.722 | M5: 155838.94 | N5: 88284.722 | O5: 3244615.8 | P5: 59347750
A6: =ROW()-3 -> 3 | B6: 定向井 | C6: 板桥（≥3500米） | D6: 2 | E6: =SUMIFS(转置表!O:O,转置表!L:L,B6,转置表!J:J,C6,转置表!M:M,D6) -> 21858 | F6: 38 | G6: =SUMIFS(转置表!T:T,转置表!L:L,B6,转置表!J:J,C6,转置表!M:M,D6) -> 182.66667 | H6: 397044.27 | I6: 414044.44 | J6: 2111417.2 | K6: 127866.67 | L6: 60888.889 | M6: 100586.49 | N6: 60888.889 | O6: 3090663.8 | P6: 37340293
A7: =ROW()-3 -> 4 | B7: 定向井 | C7: 港东 | D7: 2 | E7: =SUMIFS(转置表!O:O,转置表!L:L,B7,转置表!J:J,C7,转置表!M:M,D7) -> 3835 | F7: 38 | G7: =SUMIFS(转置表!T:T,转置表!L:L,B7,转置表!J:J,C7,转置表!M:M,D7) -> 20.104167 | H7: 43698.417 | I7: 45569.444 | J7: 177165.49 | K7: 14072.917 | L7: 6701.3889 | M7: 15207.5 | N7: 6701.3889
A8: =ROW()-3 -> 5 | B8: 定向井 | C8: 港西 | D8: 2 | E8: =SUMIFS(转置表!O:O,转置表!L:L,B8,转置表!J:J,C8,转置表!M:M,D8) -> 12133 | F8: 38 | G8: =SUMIFS(转置表!T:T,转置表!L:L,B8,转置表!J:J,C8,转置表!M:M,D8) -> 93 | H8: 202144.8 | I8: 210800 | J8: 788764.04 | K8: 65100 | L8: 31000 | M8: 53404 | N8: 31000 | O8: 2453789.6 | P8: 23277479
A9: =ROW()-3 -> 6 | B9: 定向井 | C9: 港中 | D9: 2 | E9: =SUMIFS(转置表!O:O,转置表!L:L,B9,转置表!J:J,C9,转置表!M:M,D9) -> 5497 | F9: 38 | G9: =SUMIFS(转置表!T:T,转置表!L:L,B9,转置表!J:J,C9,转置表!M:M,D9) -> 37 | H9: 80423.2 | I9: 83866.667 | J9: 350561.8 | K9: 25900 | L9: 12333.333 | M9: 19671 | N9: 12333.333
A10: =ROW()-3 -> 7 | B10: 定向井 | C10: 孔店 | D10: 2 | E10: =SUMIFS(转置表!O:O,转置表!L:L,B10,转置表!J:J,C10,转置表!M:M,D10) -> 3444 | F10: 38 | G10: =SUMIFS(转置表!T:T,转置表!L:L,B10,转置表!J:J,C10,转置表!M:M,D10) -> 30.8125 | H10: 66974.05 | I10: 69841.667 | J10: 118752.48 | K10: 21568.75 | L10: 10270.833 | M10: 0 | N10: 10270.833
A11: =ROW()-3 -> 8 | B11: 定向井 | C11: 扣村 | D11: 2 | E11: =SUMIFS(转置表!O:O,转置表!L:L,B11,转置表!J:J,C11,转置表!M:M,D11) -> 2492 | F11: 38 | G11: =SUMIFS(转置表!T:T,转置表!L:L,B11,转置表!J:J,C11,转置表!M:M,D11) -> 12 | H11: 26083.2 | I11: 27200 | J11: 125013.67 | K11: 8400 | L11: 4000 | M11: 0 | N11: 4000
A12: =ROW()-3 -> 9 | B12: 定向井 | C12: 唐家河 | D12: 2 | E12: =SUMIFS(转置表!O:O,转置表!L:L,B12,转置表!J:J,C12,转置表!M:M,D12) -> 3321 | F12: 38 | G12: =SUMIFS(转置表!T:T,转置表!L:L,B12,转置表!J:J,C12,转置表!M:M,D12) -> 20.416667 | H12: 44377.667 | I12: 46277.778 | J12: 178584.27 | K12: 14291.667 | L12: 6805.5556 | M12: 13390.5 | N12: 6805.5556
A13: =ROW()-3 -> 10 | B13: 定向井 | C13: 王官屯 | D13: 2 | E13: =SUMIFS(转置表!O:O,转置表!L:L,B13,转置表!J:J,C13,转置表!M:M,D13) -> 16455 | F13: 38 | G13: =SUMIFS(转置表!T:T,转置表!L:L,B13,转置表!J:J,C13,转置表!M:M,D13) -> 142.58333 | H13: 309919.13 | I13: 323188.89 | J13: 991491.19 | K13: 99808.333 | L13: 47527.778 | M13: 0 | N13: 47527.778 | O13: 4627576.6 | P13: 30068132
A14: =ROW()-3 -> 11 | B14: 定向井 | C14: 王徐庄 | D14: 2 | E14: =SUMIFS(转置表!O:O,转置表!L:L,B14,转置表!J:J,C14,转置表!M:M,D14) -> 2468 | F14: 38 | G14: =SUMIFS(转置表!T:T,转置表!L:L,B14,转置表!J:J,C14,转置表!M:M,D14) -> 16 | H14: 34777.6 | I14: 36266.667 | J14: 195776.57 | K14: 11200 | L14: 5333.3333 | M14: 0 | N14: 5333.3333
A15: =ROW()-3 -> 12 | B15: 定向井 | C15: 新华 | D15: 2 | E15: =SUMIFS(转置表!O:O,转置表!L:L,B15,转置表!J:J,C15,转置表!M:M,D15) -> 9956 | F15: 38 | G15: =SUMIFS(转置表!T:T,转置表!L:L,B15,转置表!J:J,C15,转置表!M:M,D15) -> 72.791667 | H15: 158219.97 | I15: 164994.44 | J15: 1080171.9 | K15: 50954.167 | L15: 24263.889 | M15: 0 | N15: 24263.889
A16: =ROW()-3 -> 13 | B16: 定向井 | C16: 羊二庄 | D16: 2 | E16: =SUMIFS(转置表!O:O,转置表!L:L,B16,转置表!J:J,C16,转置表!M:M,D16) -> 4402 | F16: 38 | G16: =SUMIFS(转置表!T:T,转置表!L:L,B16,转置表!J:J,C16,转置表!M:M,D16) -> 22 | H16: 47819.2 | I16: 49866.667 | J16: 219681.81 | K16: 15400 | L16: 7333.3333 | M16: 0 | N16: 7333.3333
A17: =ROW()-3 -> 14 | B17: 定向井 | C17: 羊三木 | D17: 2 | E17: =SUMIFS(转置表!O:O,转置表!L:L,B17,转置表!J:J,C17,转置表!M:M,D17) -> 2775 | F17: 38 | G17: =SUMIFS(转置表!T:T,转置表!L:L,B17,转置表!J:J,C17,转置表!M:M,D17) -> 21 | H17: 45645.6 | I17: 47600 | J17: 229345.42 | K17: 14700 | L17: 7000 | M17: 0 | N17: 7000
A18: =ROW()-3 -> 15 | B18: 定向井 | C18: 枣园 | D18: 2 | E18: =SUMIFS(转置表!O:O,转置表!L:L,B18,转置表!J:J,C18,转置表!M:M,D18) -> 10593 | F18: 38 | G18: =SUMIFS(转置表!T:T,转置表!L:L,B18,转置表!J:J,C18,转置表!M:M,D18) -> 71 | H18: 154325.6 | I18: 160933.33 | J18: 887015.45 | K18: 49700 | L18: 23666.667 | M18: 0 | N18: 23666.667 | O18: 1578394.2 | P18: 17030646
A19: =ROW()-3 -> 16 | B19: 水平井 | C19: 板桥 | D19: 2 | E19: =SUMIFS(转置表!O:O,转置表!L:L,B19,转置表!J:J,C19,转置表!M:M,D19) -> 19739 | F19: 38 | G19: =SUMIFS(转置表!T:T,转置表!L:L,B19,转置表!J:J,C19,转置表!M:M,D19) -> 123.8125 | H19: 269118.85 | I19: 280641.67 | J19: 1276260.2 | K19: 86668.75 | L19: 41270.833 | M19: 79872.964 | N19: 41270.833 | O19: 5696073 | P19: 34064343
A20: =ROW()-3 -> 17 | B20: 水平井 | C20: 埕海 | D20: 2 | E20: =SUMIFS(转置表!O:O,转置表!L:L,B20,转置表!J:J,C20,转置表!M:M,D20) -> 4804 | F20: 38 | G20: =SUMIFS(转置表!T:T,转置表!L:L,B20,转置表!J:J,C20,转置表!M:M,D20) -> 38.916667 | H20: 84589.267 | I20: 88211.111 | J20: 604309.57 | K20: 27241.667 | L20: 12972.222 | M20: 0 | N20: 12972.222
A21: =ROW()-3 -> 18 | B21: 水平井 | C21: 大港页岩油 | D21: 2 | E21: =SUMIFS(转置表!O:O,转置表!L:L,B21,转置表!J:J,C21,转置表!M:M,D21) -> 18574 | F21: 38 | G21: =SUMIFS(转置表!T:T,转置表!L:L,B21,转置表!J:J,C21,转置表!M:M,D21) -> 100.52431 | H21: 218499.63 | I21: 227855.09 | J21: 1862764.2 | K21: 70367.014 | L21: 33508.102 | M21: 0 | N21: 33508.102 | O21: -1830656.7 | P21: 29004677
A22: =ROW()-3 -> 19 | B22: 水平井 | C22: 枣园 | D22: 2 | E22: =SUMIFS(转置表!O:O,转置表!L:L,B22,转置表!J:J,C22,转置表!M:M,D22) -> 8000 | F22: 38 | G22: =SUMIFS(转置表!T:T,转置表!L:L,B22,转置表!J:J,C22,转置表!M:M,D22) -> 83.125 | H22: 180680.5 | I22: 188416.67 | J22: 705888 | K22: 58187.5 | L22: 27708.333 | M22: 0 | N22: 27708.333
A23: =ROW()-3 -> 20 | B23: 定向井 | C23: 板桥 | D23: 3 | E23: =SUMIFS(转置表!O:O,转置表!L:L,B23,转置表!J:J,C23,转置表!M:M,D23) -> 18653 | F23: 38 | G23: =SUMIFS(转置表!T:T,转置表!L:L,B23,转置表!J:J,C23,转置表!M:M,D23) -> 147 | H23: 319519.2 | I23: 313600 | J23: 1688506.9 | K23: 102900 | L23: 49000 | M23: 79632 | N23: 49000 | O23: 4595113.9 | P23: 45996967
A24: =ROW()-3 -> 21 | B24: 定向井 | C24: 埕海（＜4000米） | D24: 3 | E24: =SUMIFS(转置表!O:O,转置表!L:L,B24,转置表!J:J,C24,转置表!M:M,D24) -> 7594 | F24: 40 | G24: =SUMIFS(转置表!T:T,转置表!L:L,B24,转置表!J:J,C24,转置表!M:M,D24) -> 42.9375 | H24: 93328.95 | I24: 91600 | J24: 715973 | K24: 30056.25 | L24: 14312.5 | M24: 0 | N24: 14312.5 | O24: 6280277.6 | P24: 18857453
A25: =ROW()-3 -> 22 | B25: 定向井 | C25: 埕海（≥4000米） | D25: 3 | E25: =SUMIFS(转置表!O:O,转置表!L:L,B25,转置表!J:J,C25,转置表!M:M,D25) -> 23072 | F25: 40 | G25: =SUMIFS(转置表!T:T,转置表!L:L,B25,转置表!J:J,C25,转置表!M:M,D25) -> 153.79167 | H25: 334281.57 | I25: 328088.89 | J25: 2645276 | K25: 107654.17 | L25: 51263.889 | M25: 0 | N25: 51263.889 | O25: 34209204 | P25: 80955952
A26: =ROW()-3 -> 23 | B26: 定向井 | C26: 大港页岩油 | D26: 3 | E26: =SUMIFS(转置表!O:O,转置表!L:L,B26,转置表!J:J,C26,转置表!M:M,D26) -> 3732 | F26: 38 | G26: =SUMIFS(转置表!T:T,转置表!L:L,B26,转置表!J:J,C26,转置表!M:M,D26) -> 39 | H26: 84770.4 | I26: 83200 | J26: 544797.36 | K26: 27300 | L26: 13000 | M26: 0 | N26: 13000
A27: =ROW()-3 -> 24 | B27: 定向井 | C27: 港东 | D27: 3 | E27: =SUMIFS(转置表!O:O,转置表!L:L,B27,转置表!J:J,C27,转置表!M:M,D27) -> 8427 | F27: 38 | G27: =SUMIFS(转置表!T:T,转置表!L:L,B27,转置表!J:J,C27,转置表!M:M,D27) -> 113.08333 | H27: 245797.93 | I27: 241244.44 | J27: 367685.39 | K27: 79158.333 | L27: 37694.444 | M27: 0 | N27: 37694.444
A28: =ROW()-3 -> 25 | B28: 定向井 | C28: 歧口 | D28: 3 | E28: =SUMIFS(转置表!O:O,转置表!L:L,B28,转置表!J:J,C28,转置表!M:M,D28) -> 10314 | F28: 38 | G28: =SUMIFS(转置表!T:T,转置表!L:L,B28,转置表!J:J,C28,转置表!M:M,D28) -> 126 | H28: 273873.6 | I28: 268800 | J28: 1473891.2 | K28: 88200 | L28: 42000 | M28: 0 | N28: 42000
A29: =ROW()-3 -> 26 | B29: 定向井 | C29: 唐东（开发井） | D29: 3 | E29: =SUMIFS(转置表!O:O,转置表!L:L,B29,转置表!J:J,C29,转置表!M:M,D29) -> 30995 | F29: 38 | G29: =SUMIFS(转置表!T:T,转置表!L:L,B29,转置表!J:J,C29,转置表!M:M,D29) -> 201.08333 | H29: 437074.73 | I29: 428977.78 | J29: 3428013.7 | K29: 140758.33 | L29: 67027.778 | M29: 83800.52 | N29: 67027.778 | O29: 19052482 | P29: 82042278
A30: =ROW()-3 -> 27 | B30: 定向井 | C30: 唐东（探评井） | D30: 3 | E30: =SUMIFS(转置表!O:O,转置表!L:L,B30,转置表!J:J,C30,转置表!M:M,D30) -> 27892 | F30: 38 | G30: =SUMIFS(转置表!T:T,转置表!L:L,B30,转置表!J:J,C30,转置表!M:M,D30) -> 222.89583 | H30: 484486.38 | I30: 475511.11 | J30: 3804249.3 | K30: 156027.08 | L30: 74298.611 | M30: 100169.56 | N30: 74298.611 | O30: 5933178.9 | P30: 77953922
A31: =ROW()-3 -> 28 | B31: 定向井 | C31: 新华 | D31: 3 | E31: =SUMIFS(转置表!O:O,转置表!L:L,B31,转置表!J:J,C31,转置表!M:M,D31) -> 42074 | F31: 38 | G31: =SUMIFS(转置表!T:T,转置表!L:L,B31,转置表!J:J,C31,转置表!M:M,D31) -> 377.7325 | H31: 821039.36 | I31: 805829.33 | J31: 4782603.2 | K31: 264412.75 | L31: 125910.83 | M31: 0 | N31: 125910.83 | O31: 24342335 | P31: 1.5713417e+08
A32: =ROW()-3 -> 29 | B32: 水平井 | C32: 板桥 | D32: 3 | E32: =SUMIFS(转置表!O:O,转置表!L:L,B32,转置表!J:J,C32,转置表!M:M,D32) -> 0 | F32: 38 | G32: =SUMIFS(转置表!T:T,转置表!L:L,B32,转置表!J:J,C32,转置表!M:M,D32) -> 0 | H32: #DIV/0! | I32: #DIV/0! | J32: 185393.26 | K32: #DIV/0! | L32: #DIV/0! | M32: 10169.057 | N32: #DIV/0!
A33: =ROW()-3 -> 30 | B33: 水平井 | C33: 埕海 | D33: 3 | E33: =SUMIFS(转置表!O:O,转置表!L:L,B33,转置表!J:J,C33,转置表!M:M,D33) -> 8218 | F33: 38 | G33: =SUMIFS(转置表!T:T,转置表!L:L,B33,转置表!J:J,C33,转置表!M:M,D33) -> 62 | H33: 134763.2 | I33: 132266.67 | J33: 1033766.9 | K33: 43400 | L33: 20666.667 | M33: 0 | N33: 20666.667
A34: =ROW()-3 -> 31 | B34: 水平井 | C34: 大港页岩油 | D34: 3 | E34: =SUMIFS(转置表!O:O,转置表!L:L,B34,转置表!J:J,C34,转置表!M:M,D34) -> 43535 | F34: 38 | G34: =SUMIFS(转置表!T:T,转置表!L:L,B34,转置表!J:J,C34,转置表!M:M,D34) -> 389 | H34: 845530.4 | I34: 829866.67 | J34: 7231651.1 | K34: 272300 | L34: 129666.67 | M34: 0 | N34: 129666.67 | O34: 1368516.9 | P34: 182709100
A35: =ROW()-3 -> 32 | B35: 水平井 | C35: 唐东 | D35: 3 | E35: =SUMIFS(转置表!O:O,转置表!L:L,B35,转置表!J:J,C35,转置表!M:M,D35) -> 5842 | F35: 38 | G35: =SUMIFS(转置表!T:T,转置表!L:L,B35,转置表!J:J,C35,转置表!M:M,D35) -> 46.71 | H35: 101528.86 | I35: 99648 | J35: 888900.3 | K35: 32697 | L35: 15570 | M35: 36624.232 | N35: 15570
A36: =ROW()-3 -> 33 | B36: 定向井 | C36: 板桥 | D36: 4 | E36: =SUMIFS(转置表!O:O,转置表!L:L,B36,转置表!J:J,C36,转置表!M:M,D36) -> 14474 | F36: 38 | G36: =SUMIFS(转置表!T:T,转置表!L:L,B36,转置表!J:J,C36,转置表!M:M,D36) -> 152.77083 | H36: 332062.68 | I36: 325911.11 | J36: 1983628.5 | K36: 106939.58 | L36: 50923.611 | M36: 84135 | N36: 50923.611 | O36: 17977484 | P36: 59828852

Sheet 6米费定额 
A1: 附件1-6
A3: 大港油区米费定额
H4: 单位：元/米•人
A5: 序号 | B5: 井型 | C5: 区块 | D5: 开次 | E5: 累计井深 | F5: 累计钻完井周期 | G5: 累计费用 | H5: 米费定额 | I5: 备注
A6: =ROW()-5 -> 1 | B6: 定向井 | C6: 板桥（＜2500米） | D6: 2 | E6: =SUMIFS(转置表!O:O,转置表!L:L,B6,转置表!J:J,C6,转置表!M:M,D6) -> 3957 | F6: =SUMIFS(转置表!T:T,转置表!L:L,B6,转置表!J:J,C6,转置表!M:M,D6) -> 25 | G6: =E6*H6*38 -> 54340 | H6: =(1300*2.2/30)*F6/E6*0.6 -> 0.36138489 | K6: =COUNTIFS(转置表!L:L,B6,转置表!J:J,C6,转置表!M:M,D6) -> 2
A7: =ROW()-5 -> 2 | B7: 定向井 | C7: 板桥（＜3500米） | D7: 2 | E7: =SUMIFS(转置表!O:O,转置表!L:L,B7,转置表!J:J,C7,转置表!M:M,D7) -> 44234 | F7: =SUMIFS(转置表!T:T,转置表!L:L,B7,转置表!J:J,C7,转置表!M:M,D7) -> 264.85417 | G7: =E7*H7*38 -> 575687.02 | H7: =(1300*2.2/30)*F7/E7*0.6 -> 0.342489 | K7: =COUNTIFS(转置表!L:L,B7,转置表!J:J,C7,转置表!M:M,D7) -> 14
A8: =ROW()-5 -> 3 | B8: 定向井 | C8: 板桥（≥3500米） | D8: 2 | E8: =SUMIFS(转置表!O:O,转置表!L:L,B8,转置表!J:J,C8,转置表!M:M,D8) -> 21858 | F8: =SUMIFS(转置表!T:T,转置表!L:L,B8,转置表!J:J,C8,转置表!M:M,D8) -> 182.66667 | G8: =E8*H8*38 -> 397044.27 | H8: =(1300*2.2/30)*F8/E8*0.6 -> 0.47801873 | K8: =COUNTIFS(转置表!L:L,B8,转置表!J:J,C8,转置表!M:M,D8) -> 6
A9: =ROW()-5 -> 4 | B9: 定向井 | C9: 港东 | D9: 2 | E9: =SUMIFS(转置表!O:O,转置表!L:L,B9,转置表!J:J,C9,转置表!M:M,D9) -> 3835 | F9: =SUMIFS(转置表!T:T,转置表!L:L,B9,转置表!J:J,C9,转置表!M:M,D9) -> 20.104167 | G9: =E9*H9*38 -> 43698.417 | H9: =(1300*2.2/30)*F9/E9*0.6 -> 0.29985876 | K9: =COUNTIFS(转置表!L:L,B9,转置表!J:J,C9,转置表!M:M,D9) -> 2
A10: =ROW()-5 -> 5 | B10: 定向井 | C10: 港西 | D10: 2 | E10: =SUMIFS(转置表!O:O,转置表!L:L,B10,转置表!J:J,C10,转置表!M:M,D10) -> 12133 | F10: =SUMIFS(转置表!T:T,转置表!L:L,B10,转置表!J:J,C10,转置表!M:M,D10) -> 93 | G10: =E10*H10*38 -> 202144.8 | H10: =(1300*2.2/30)*F10/E10*0.6 -> 0.43844062 | K10: =COUNTIFS(转置表!L:L,B10,转置表!J:J,C10,转置表!M:M,D10) -> 8
A11: =ROW()-5 -> 6 | B11: 定向井 | C11: 港中 | D11: 2 | E11: =SUMIFS(转置表!O:O,转置表!L:L,B11,转置表!J:J,C11,转置表!M:M,D11) -> 5497 | F11: =SUMIFS(转置表!T:T,转置表!L:L,B11,转置表!J:J,C11,转置表!M:M,D11) -> 37 | G11: =E11*H11*38 -> 80423.2 | H11: =(1300*2.2/30)*F11/E11*0.6 -> 0.38501001 | K11: =COUNTIFS(转置表!L:L,B11,转置表!J:J,C11,转置表!M:M,D11) -> 2
A12: =ROW()-5 -> 7 | B12: 定向井 | C12: 孔店 | D12: 2 | E12: =SUMIFS(转置表!O:O,转置表!L:L,B12,转置表!J:J,C12,转置表!M:M,D12) -> 3444 | F12: =SUMIFS(转置表!T:T,转置表!L:L,B12,转置表!J:J,C12,转置表!M:M,D12) -> 30.8125 | G12: =E12*H12*38 -> 66974.05 | H12: =(1300*2.2/30)*F12/E12*0.6 -> 0.51175232 | K12: =COUNTIFS(转置表!L:L,B12,转置表!J:J,C12,转置表!M:M,D12) -> 2
A13: =ROW()-5 -> 8 | B13: 定向井 | C13: 扣村 | D13: 2 | E13: =SUMIFS(转置表!O:O,转置表!L:L,B13,转置表!J:J,C13,转置表!M:M,D13) -> 2492 | F13: =SUMIFS(转置表!T:T,转置表!L:L,B13,转置表!J:J,C13,转置表!M:M,D13) -> 12 | G13: =E13*H13*38 -> 26083.2 | H13: =(1300*2.2/30)*F13/E13*0.6 -> 0.27544141 | I13: 扣301 | K13: =COUNTIFS(转置表!L:L,B13,转置表!J:J,C13,转置表!M:M,D13) -> 1
A14: =ROW()-5 -> 9 | B14: 定向井 | C14: 唐家河 | D14: 2 | E14: =SUMIFS(转置表!O:O,转置表!L:L,B14,转置表!J:J,C14,转置表!M:M,D14) -> 3321 | F14: =SUMIFS(转置表!T:T,转置表!L:L,B14,转置表!J:J,C14,转置表!M:M,D14) -> 20.416667 | G14: =E14*H14*38 -> 44377.667 | H14: =(1300*2.2/30)*F14/E14*0.6 -> 0.35165111 | K14: =COUNTIFS(转置表!L:L,B14,转置表!J:J,C14,转置表!M:M,D14) -> 1
A15: =ROW()-5 -> 10 | B15: 定向井 | C15: 王官屯 | D15: 2 | E15: =SUMIFS(转置表!O:O,转置表!L:L,B15,转置表!J:J,C15,转置表!M:M,D15) -> 16455 | F15: =SUMIFS(转置表!T:T,转置表!L:L,B15,转置表!J:J,C15,转置表!M:M,D15) -> 142.58333 | G15: =E15*H15*38 -> 309919.13 | H15: =(1300*2.2/30)*F15/E15*0.6 -> 0.49564064 | K15: =COUNTIFS(转置表!L:L,B15,转置表!J:J,C15,转置表!M:M,D15) -> 5
A16: =ROW()-5 -> 11 | B16: 定向井 | C16: 王徐庄 | D16: 2 | E16: =SUMIFS(转置表!O:O,转置表!L:L,B16,转置表!J:J,C16,转置表!M:M,D16) -> 2468 | F16: =SUMIFS(转置表!T:T,转置表!L:L,B16,转置表!J:J,C16,转置表!M:M,D16) -> 16 | G16: =E16*H16*38 -> 34777.6 | H16: =(1300*2.2/30)*F16/E16*0.6 -> 0.37082658 | K16: =COUNTIFS(转置表!L:L,B16,转置表!J:J,C16,转置表!M:M,D16) -> 1
A17: =ROW()-5 -> 12 | B17: 定向井 | C17: 新华 | D17: 2 | E17: =SUMIFS(转置表!O:O,转置表!L:L,B17,转置表!J:J,C17,转置表!M:M,D17) -> 9956 | F17: =SUMIFS(转置表!T:T,转置表!L:L,B17,转置表!J:J,C17,转置表!M:M,D17) -> 72.791667 | G17: =E17*H17*38 -> 158219.97 | H17: =(1300*2.2/30)*F17/E17*0.6 -> 0.41820845 | K17: =COUNTIFS(转置表!L:L,B17,转置表!J:J,C17,转置表!M:M,D17) -> 2
A18: =ROW()-5 -> 13 | B18: 定向井 | C18: 羊二庄 | D18: 2 | E18: =SUMIFS(转置表!O:O,转置表!L:L,B18,转置表!J:J,C18,转置表!M:M,D18) -> 4402 | F18: =SUMIFS(转置表!T:T,转置表!L:L,B18,转置表!J:J,C18,转置表!M:M,D18) -> 22 | G18: =E18*H18*38 -> 47819.2 | H18: =(1300*2.2/30)*F18/E18*0.6 -> 0.28587006 | K18: =COUNTIFS(转置表!L:L,B18,转置表!J:J,C18,转置表!M:M,D18) -> 2
A19: =ROW()-5 -> 14 | B19: 定向井 | C19: 羊三木 | D19: 2 | E19: =SUMIFS(转置表!O:O,转置表!L:L,B19,转置表!J:J,C19,转置表!M:M,D19) -> 2775 | F19: =SUMIFS(转置表!T:T,转置表!L:L,B19,转置表!J:J,C19,转置表!M:M,D19) -> 21 | G19: =E19*H19*38 -> 45645.6 | H19: =(1300*2.2/30)*F19/E19*0.6 -> 0.43286486 | K19: =COUNTIFS(转置表!L:L,B19,转置表!J:J,C19,转置表!M:M,D19) -> 1
A20: =ROW()-5 -> 15 | B20: 定向井 | C20: 枣园 | D20: 2 | E20: =SUMIFS(转置表!O:O,转置表!L:L,B20,转置表!J:J,C20,转置表!M:M,D20) -> 10593 | F20: =SUMIFS(转置表!T:T,转置表!L:L,B20,转置表!J:J,C20,转置表!M:M,D20) -> 71 | G20: =E20*H20*38 -> 154325.6 | H20: =(1300*2.2/30)*F20/E20*0.6 -> 0.38338525 | K20: =COUNTIFS(转置表!L:L,B20,转置表!J:J,C20,转置表!M:M,D20) -> 4
A21: =ROW()-5 -> 16 | B21: 水平井 | C21: 板桥 | D21: 2 | E21: =SUMIFS(转置表!O:O,转置表!L:L,B21,转置表!J:J,C21,转置表!M:M,D21) -> 19739 | F21: =SUMIFS(转置表!T:T,转置表!L:L,B21,转置表!J:J,C21,转置表!M:M,D21) -> 123.8125 | G21: =E21*H21*38 -> 269118.85 | H21: =(1300*2.2/30)*F21/E21*0.6 -> 0.35878591 | K21: =COUNTIFS(转置表!L:L,B21,转置表!J:J,C21,转置表!M:M,D21) -> 8
A22: =ROW()-5 -> 17 | B22: 水平井 | C22: 埕海 | D22: 2 | E22: =SUMIFS(转置表!O:O,转置表!L:L,B22,转置表!J:J,C22,转置表!M:M,D22) -> 4804 | F22: =SUMIFS(转置表!T:T,转置表!L:L,B22,转置表!J:J,C22,转置表!M:M,D22) -> 38.916667 | G22: =E22*H22*38 -> 84589.267 | H22: =(1300*2.2/30)*F22/E22*0.6 -> 0.4633708 | K22: =COUNTIFS(转置表!L:L,B22,转置表!J:J,C22,转置表!M:M,D22) -> 1
A23: =ROW()-5 -> 18 | B23: 水平井 | C23: 大港页岩油 | D23: 2 | E23: =SUMIFS(转置表!O:O,转置表!L:L,B23,转置表!J:J,C23,转置表!M:M,D23) -> 18574 | F23: =SUMIFS(转置表!T:T,转置表!L:L,B23,转置表!J:J,C23,转置表!M:M,D23) -> 100.52431 | G23: =E23*H23*38 -> 218499.63 | H23: =(1300*2.2/30)*F23/E23*0.6 -> 0.309572 | K23: =COUNTIFS(转置表!L:L,B23,转置表!J:J,C23,转置表!M:M,D23) -> 3
A24: =ROW()-5 -> 19 | B24: 水平井 | C24: 枣园 | D24: 2 | E24: =SUMIFS(转置表!O:O,转置表!L:L,B24,转置表!J:J,C24,转置表!M:M,D24) -> 8000 | F24: =SUMIFS(转置表!T:T,转置表!L:L,B24,转置表!J:J,C24,转置表!M:M,D24) -> 83.125 | G24: =E24*H24*38 -> 180680.5 | H24: =(1300*2.2/30)*F24/E24*0.6 -> 0.59434375 | K24: =COUNTIFS(转置表!L:L,B24,转置表!J:J,C24,转置表!M:M,D24) -> 2
A25: =ROW()-5 -> 20 | B25: 定向井 | C25: 板桥 | D25: 3 | E25: =SUMIFS(转置表!O:O,转置表!L:L,B25,转置表!J:J,C25,转置表!M:M,D25) -> 18653 | F25: =SUMIFS(转置表!T:T,转置表!L:L,B25,转置表!J:J,C25,转置表!M:M,D25) -> 147 | G25: =E25*H25*38 -> 319519.2 | H25: =(1300*2.2/30)*F25/E25*0.6 -> 0.45078004 | K25: =COUNTIFS(转置表!L:L,B25,转置表!J:J,C25,转置表!M:M,D25) -> 5
... A35: =ROW()-5 -> 30 | B35: 水平井 | C35: 埕海 | D35: 3 | E35: =SUMIFS(转置表!O:O,转置表!L:L,B35,转置表!J:J,C35,转置表!M:M,D35) -> 8218 | F35: =SUMIFS(转置表!T:T,转置表!L:L,B35,转置表!J:J,C35,转置表!M:M,D35) -> 62 | G35: =E35*H35*38 -> 134763.2 | H35: =(1300*2.2/30)*F35/E35*0.6 -> 0.43154052 | K35: =COUNTIFS(转置表!L:L,B35,转置表!J:J,C35,转置表!M:M,D35) -> 2
A36: =ROW()-5 -> 31 | B36: 水平井 | C36: 大港页岩油 | D36: 3 | E36: =SUMIFS(转置表!O:O,转置表!L:L,B36,转置表!J:J,C36,转置表!M:M,D36) -> 43535 | F36: =SUMIFS(转置表!T:T,转置表!L:L,B36,转置表!J:J,C36,转置表!M:M,D36) -> 389 | G36: =E36*H36*38 -> 845530.4 | H36: =(1300*2.2/30)*F36/E36*0.6 -> 0.51110141 | I36: 华页1、官页5-5-1 | K36: =COUNTIFS(转置表!L:L,B36,转置表!J:J,C36,转置表!M:M,D36) -> 7
A37: =ROW()-5 -> 32 | B37: 水平井 | C37: 唐东 | D37: 3 | E37: =SUMIFS(转置表!O:O,转置表!L:L,B37,转置表!J:J,C37,转置表!M:M,D37) -> 5842 | F37: =SUMIFS(转置表!T:T,转置表!L:L,B37,转置表!J:J,C37,转置表!M:M,D37) -> 46.71 | G37: =E37*H37*38 -> 101528.86 | H37: =(1300*2.2/30)*F37/E37*0.6 -> 0.45734543 | K37: =COUNTIFS(转置表!L:L,B37,转置表!J:J,C37,转置表!M:M,D37) -> 1
A38: =ROW()-5 -> 33 | B38: 定向井 | C38: 板桥 | D38: 4 | E38: =SUMIFS(转置表!O:O,转置表!L:L,B38,转置表!J:J,C38,转置表!M:M,D38) -> 14474 | F38: =SUMIFS(转置表!T:T,转置表!L:L,B38,转置表!J:J,C38,转置表!M:M,D38) -> 152.77083 | G38: =E38*H38*38 -> 332062.68 | H38: =(1300*2.2/30)*F38/E38*0.6 -> 0.60373716 | K38: =COUNTIFS(转置表!L:L,B38,转置表!J:J,C38,转置表!M:M,D38) -> 3
B39: 定向井 | C39: 常探1 | D39: 3 | E39: 6082 | F39: 52.75 | G39: =E39*H39*38 -> 114657.4 | H39: =(1300*2.2/30)*F39/E39*0.6 -> 0.49610326
B40: 定向井 | C40: 滨188X1 | D40: 3 | E40: 5220 | F40: 53.5 | G40: =E40*H40*38 -> 116287.6 | H40: =(1300*2.2/30)*F40/E40*0.6 -> 0.58624521
B41: 定向井 | C41: 孔101-9 | D41: 2 | E41: 1761 | F41: 10 | G41: =E41*H41*38 -> 21736 | H41: =(1300*2.2/30)*F41/E41*0.6 -> 0.32481545
B42: 定向井 | C42: 家29-30 | D42: 2 | E42: 2327 | F42: 14 | G42: =E42*H42*38 -> 30430.4 | H42: =(1300*2.2/30)*F42/E42*0.6 -> 0.34413408
B43: 定向井 | C43: 官40-67 | D43: 2 | E43: 3092 | F43: 17 | G43: =E43*H43*38 -> 36951.2 | H43: =(1300*2.2/30)*F43/E43*0.6 -> 0.314489
B44: 水平井 | C44: 板70-20H | D44: 3 | E44: 2695 | F44: 25.5 | G44: =E44*H44*38 -> 55426.8 | H44: =(1300*2.2/30)*F44/E44*0.6 -> 0.54122449
B45: 水平井 | C45: 板69-22H | D45: 3 | E45: 2720 | F45: 23.1 | G45: =E45*H45*38 -> 50210.16 | H45: =(1300*2.2/30)*F45/E45*0.6 -> 0.48577941
B46: 定向井 | C46: 灯探1 | D46: 3 | E46: 3632 | F46: 27 | G46: =E46*H46*38 -> 58687.2 | H46: =(1300*2.2/30)*F46/E46*0.6 -> 0.42522026
B47: 定向井 | C47: 官40-61 | D47: 2 | E47: 3092 | F47: 18.5 | G47: =E47*H47*38 -> 40211.6 | H47: =(1300*2.2/30)*F47/E47*0.6 -> 0.34223803
B48: 定向井 | C48: 塘39-6 | D48: 3 | E48: 4540 | F48: 27.5 | G48: =E48*H48*38 -> 59774 | H48: =(1300*2.2/30)*F48/E48*0.6 -> 0.34647577

Sheet 7一般材料定额
A1: 附件1-7
A2: 大港油区区块一般材料定额
I3: 单位：元/米
A4: 序号 | B4: 井型 | C4: 区块 | D4: 开次 | E4: 累计井深 | F4: 累计钻完井周期 | G4: 50型累计费用 | H4: 70型累计费用 | I4: 50型定额 | J4: 70型定额 | K4: 备注 | Q4: 修订说明：
A5: =ROW()-4 -> 1 | B5: 定向井 | C5: 板桥（＜2500米） | D5: 2 | E5: =SUMIFS(转置表!O:O,转置表!L:L,B5,转置表!J:J,C5,转置表!M:M,D5) -> 3957 | F5: =SUMIFS(转置表!T:T,转置表!L:L,B5,转置表!J:J,C5,转置表!M:M,D5) -> 25 | G5: =E5*I5 -> 53125 | H5: =E5*J5 -> 60208.333 | I5: =(75000/30)*F5/E5*0.85 -> 13.425575 | J5: =(85000/30)*F5/E5*0.85 -> 15.215652 | Q5: 2.10修订：考虑完井因素，一般材料二开井下浮15%，三开井下浮20% | T5: 13.425575 | U5: =ROUND(T5,2) -> 13.43 | V5: 15.215652 | W5: =ROUND(V5,2) -> 15.22
A6: =ROW()-4 -> 2 | B6: 定向井 | C6: 板桥（＜3500米） | D6: 2 | E6: =SUMIFS(转置表!O:O,转置表!L:L,B6,转置表!J:J,C6,转置表!M:M,D6) -> 44234 | F6: =SUMIFS(转置表!T:T,转置表!L:L,B6,转置表!J:J,C6,转置表!M:M,D6) -> 264.85417 | G6: =E6*I6 -> 562815.1 | H6: =E6*J6 -> 637857.12 | I6: =(75000/30)*F6/E6*0.85 -> 12.723586 | J6: =(85000/30)*F6/E6*0.85 -> 14.420064 | Q6: 2.13日修订：取心定额按60%核算 | T6: 13.055197 | U6: =ROUND(T6,2) -> 13.06 | V6: 14.79589 | W6: =ROUND(V6,2) -> 14.8
A7: =ROW()-4 -> 3 | B7: 定向井 | C7: 板桥（≥3500米） | D7: 2 | E7: =SUMIFS(转置表!O:O,转置表!L:L,B7,转置表!J:J,C7,转置表!M:M,D7) -> 21858 | F7: =SUMIFS(转置表!T:T,转置表!L:L,B7,转置表!J:J,C7,转置表!M:M,D7) -> 182.66667 | G7: =E7*I7 -> 388166.67 | H7: =E7*J7 -> 439922.22 | I7: =(75000/30)*F7/E7*0.85 -> 17.758563 | J7: =(85000/30)*F7/E7*0.85 -> 20.126371 | M7: 定向井 | N7: 板桥 | O7: =N7=C7 -> FALSE | T7: 17.758563 | U7: =ROUND(T7,2) -> 17.76 | V7: 20.126371 | W7: =ROUND(V7,2) -> 20.13
A8: =ROW()-4 -> 4 | B8: 定向井 | C8: 港东 | D8: 2 | E8: =SUMIFS(转置表!O:O,转置表!L:L,B8,转置表!J:J,C8,转置表!M:M,D8) -> 3835 | F8: =SUMIFS(转置表!T:T,转置表!L:L,B8,转置表!J:J,C8,转置表!M:M,D8) -> 20.104167 | G8: =E8*I8 -> 42721.354 | H8: =E8*J8 -> 48417.535 | I8: =(75000/30)*F8/E8*0.85 -> 11.139858 | J8: =(85000/30)*F8/E8*0.85 -> 12.625172 | M8: 定向井 | N8: 港东 | O8: =N8=C8 -> TRUE | T8: 11.139858 | U8: =ROUND(T8,2) -> 11.14 | V8: 12.625172 | W8: =ROUND(V8,2) -> 12.63
A9: =ROW()-4 -> 5 | B9: 定向井 | C9: 港西 | D9: 2 | E9: =SUMIFS(转置表!O:O,转置表!L:L,B9,转置表!J:J,C9,转置表!M:M,D9) -> 12133 | F9: =SUMIFS(转置表!T:T,转置表!L:L,B9,转置表!J:J,C9,转置表!M:M,D9) -> 93 | G9: =E9*I9 -> 197625 | H9: =E9*J9 -> 223975 | I9: =(75000/30)*F9/E9*0.85 -> 16.288222 | J9: =(85000/30)*F9/E9*0.85 -> 18.459985 | M9: 定向井 | N9: 港西 | O9: =N9=C9 -> TRUE | T9: 16.288222 | U9: =ROUND(T9,2) -> 16.29 | V9: 18.459985 | W9: =ROUND(V9,2) -> 18.46
A10: =ROW()-4 -> 6 | B10: 定向井 | C10: 港中 | D10: 2 | E10: =SUMIFS(转置表!O:O,转置表!L:L,B10,转置表!J:J,C10,转置表!M:M,D10) -> 5497 | F10: =SUMIFS(转置表!T:T,转置表!L:L,B10,转置表!J:J,C10,转置表!M:M,D10) -> 37 | G10: =E10*I10 -> 78625 | H10: =E10*J10 -> 89108.333 | I10: =(75000/30)*F10/E10*0.85 -> 14.303256 | J10: =(85000/30)*F10/E10*0.85 -> 16.210357 | M10: 定向井 | N10: 港中 | O10: =N10=C10 -> TRUE | T10: 14.303256 | U10: =ROUND(T10,2) -> 14.3 | V10: 16.210357 | W10: =ROUND(V10,2) -> 16.21
A11: =ROW()-4 -> 7 | B11: 定向井 | C11: 孔店 | D11: 2 | E11: =SUMIFS(转置表!O:O,转置表!L:L,B11,转置表!J:J,C11,转置表!M:M,D11) -> 3444 | F11: =SUMIFS(转置表!T:T,转置表!L:L,B11,转置表!J:J,C11,转置表!M:M,D11) -> 30.8125 | G11: =E11*I11 -> 65476.562 | H11: =E11*J11 -> 74206.771 | I11: =(75000/30)*F11/E11*0.85 -> 19.011778 | J11: =(85000/30)*F11/E11*0.85 -> 21.546681 | M11: 定向井 | N11: 孔店 | O11: =N11=C11 -> TRUE | T11: 19.011778 | U11: =ROUND(T11,2) -> 19.01 | V11: 21.546681 | W11: =ROUND(V11,2) -> 21.55
A12: =ROW()-4 -> 8 | B12: 定向井 | C12: 扣村 | D12: 2 | E12: =SUMIFS(转置表!O:O,转置表!L:L,B12,转置表!J:J,C12,转置表!M:M,D12) -> 2492 | F12: =SUMIFS(转置表!T:T,转置表!L:L,B12,转置表!J:J,C12,转置表!M:M,D12) -> 12 | G12: =E12*I12 -> 25500 | H12: =E12*J12 -> 28900 | I12: =(75000/30)*F12/E12*0.85 -> 10.232745 | J12: =(85000/30)*F12/E12*0.85 -> 11.597111 | K12: 扣301 | M12: 定向井 | N12: 扣村 | O12: =N12=C12 -> TRUE | T12: 10.232745 | U12: =ROUND(T12,2) -> 10.23 | V12: 11.597111 | W12: =ROUND(V12,2) -> 11.6
A13: =ROW()-4 -> 9 | B13: 定向井 | C13: 唐家河 | D13: 2 | E13: =SUMIFS(转置表!O:O,转置表!L:L,B13,转置表!J:J,C13,转置表!M:M,D13) -> 3321 | F13: =SUMIFS(转置表!T:T,转置表!L:L,B13,转置表!J:J,C13,转置表!M:M,D13) -> 20.416667 | G13: =E13*I13 -> 43385.417 | H13: =E13*J13 -> 49170.139 | I13: =(75000/30)*F13/E13*0.85 -> 13.063962 | J13: =(85000/30)*F13/E13*0.85 -> 14.805823 | M13: 定向井 | N13: 唐家河 | O13: =N13=C13 -> TRUE | T13: 13.063962 | U13: =ROUND(T13,2) -> 13.06 | V13: 14.805823 | W13: =ROUND(V13,2) -> 14.81
A14: =ROW()-4 -> 10 | B14: 定向井 | C14: 王官屯 | D14: 2 | E14: =SUMIFS(转置表!O:O,转置表!L:L,B14,转置表!J:J,C14,转置表!M:M,D14) -> 16455 | F14: =SUMIFS(转置表!T:T,转置表!L:L,B14,转置表!J:J,C14,转置表!M:M,D14) -> 142.58333 | G14: =E14*I14 -> 302989.58 | H14: =E14*J14 -> 343388.19 | I14: =(75000/30)*F14/E14*0.85 -> 18.413223 | J14: =(85000/30)*F14/E14*0.85 -> 20.868319 | M14: 定向井 | N14: 王官屯 | O14: =N14=C14 -> TRUE | T14: 18.916442 | U14: =ROUND(T14,2) -> 18.92 | V14: 21.438635 | W14: =ROUND(V14,2) -> 21.44
A15: =ROW()-4 -> 11 | B15: 定向井 | C15: 王徐庄 | D15: 2 | E15: =SUMIFS(转置表!O:O,转置表!L:L,B15,转置表!J:J,C15,转置表!M:M,D15) -> 2468 | F15: =SUMIFS(转置表!T:T,转置表!L:L,B15,转置表!J:J,C15,转置表!M:M,D15) -> 16 | G15: =E15*I15 -> 34000 | H15: =E15*J15 -> 38533.333 | I15: =(75000/30)*F15/E15*0.85 -> 13.776337 | J15: =(85000/30)*F15/E15*0.85 -> 15.613182 | M15: 定向井 | N15: 王徐庄 | O15: =N15=C15 -> TRUE | T15: 13.776337 | U15: =ROUND(T15,2) -> 13.78 | V15: 15.613182 | W15: =ROUND(V15,2) -> 15.61
A16: =ROW()-4 -> 12 | B16: 定向井 | C16: 新华 | D16: 2 | E16: =SUMIFS(转置表!O:O,转置表!L:L,B16,转置表!J:J,C16,转置表!M:M,D16) -> 9956 | F16: =SUMIFS(转置表!T:T,转置表!L:L,B16,转置表!J:J,C16,转置表!M:M,D16) -> 72.791667 | G16: =E16*I16 -> 154682.29 | H16: =E16*J16 -> 175306.6 | I16: =(75000/30)*F16/E16*0.85 -> 15.53659 | J16: =(85000/30)*F16/E16*0.85 -> 17.608136 | M16: 定向井 | N16: 新华 | O16: =N16=C16 -> TRUE | T16: 15.53659 | U16: =ROUND(T16,2) -> 15.54 | V16: 17.608136 | W16: =ROUND(V16,2) -> 17.61
A17: =ROW()-4 -> 13 | B17: 定向井 | C17: 羊二庄 | D17: 2 | E17: =SUMIFS(转置表!O:O,转置表!L:L,B17,转置表!J:J,C17,转置表!M:M,D17) -> 4402 | F17: =SUMIFS(转置表!T:T,转置表!L:L,B17,转置表!J:J,C17,转置表!M:M,D17) -> 22 | G17: =E17*I17 -> 46750 | H17: =E17*J17 -> 52983.333 | I17: =(75000/30)*F17/E17*0.85 -> 10.620173 | J17: =(85000/30)*F17/E17*0.85 -> 12.036196 | M17: 定向井 | N17: 羊二庄 | O17: =N17=C17 -> TRUE | T17: 10.620173 | U17: =ROUND(T17,2) -> 10.62 | V17: 12.036196 | W17: =ROUND(V17,2) -> 12.04
A18: =ROW()-4 -> 14 | B18: 定向井 | C18: 羊三木 | D18: 2 | E18: =SUMIFS(转置表!O:O,转置表!L:L,B18,转置表!J:J,C18,转置表!M:M,D18) -> 2775 | F18: =SUMIFS(转置表!T:T,转置表!L:L,B18,转置表!J:J,C18,转置表!M:M,D18) -> 21 | G18: =E18*I18 -> 44625 | H18: =E18*J18 -> 50575 | I18: =(75000/30)*F18/E18*0.85 -> 16.081081 | J18: =(85000/30)*F18/E18*0.85 -> 18.225225 | M18: 定向井 | N18: 羊三木 | O18: =N18=C18 -> TRUE | T18: 16.081081 | U18: =ROUND(T18,2) -> 16.08 | V18: 18.225225 | W18: =ROUND(V18,2) -> 18.23
A19: =ROW()-4 -> 15 | B19: 定向井 | C19: 枣园 | D19: 2 | E19: =SUMIFS(转置表!O:O,转置表!L:L,B19,转置表!J:J,C19,转置表!M:M,D19) -> 10593 | F19: =SUMIFS(转置表!T:T,转置表!L:L,B19,转置表!J:J,C19,转置表!M:M,D19) -> 71 | G19: =E19*I19 -> 150875 | H19: =E19*J19 -> 170991.67 | I19: =(75000/30)*F19/E19*0.85 -> 14.242896 | J19: =(85000/30)*F19/E19*0.85 -> 16.141949 | M19: 定向井 | N19: 枣园 | O19: =N19=C19 -> TRUE | T19: 14.242896 | U19: =ROUND(T19,2) -> 14.24 | V19: 16.141949 | W19: =ROUND(V19,2) -> 16.14
A20: =ROW()-4 -> 16 | B20: 水平井 | C20: 板桥 | D20: 2 | E20: =SUMIFS(转置表!O:O,转置表!L:L,B20,转置表!J:J,C20,转置表!M:M,D20) -> 19739 | F20: =SUMIFS(转置表!T:T,转置表!L:L,B20,转置表!J:J,C20,转置表!M:M,D20) -> 123.8125 | G20: =E20*I20 -> 263101.56 | H20: =E20*J20 -> 298181.77 | I20: =(75000/30)*F20/E20*0.85 -> 13.329022 | J20: =(85000/30)*F20/E20*0.85 -> 15.106225 | M20: 水平井 | N20: 板桥 | O20: =N20=C20 -> TRUE | T20: 13.329022 | U20: =ROUND(T20,2) -> 13.33 | V20: 15.106225 | W20: =ROUND(V20,2) -> 15.11
A21: =ROW()-4 -> 17 | B21: 水平井 | C21: 埕海 | D21: 2 | E21: =SUMIFS(转置表!O:O,转置表!L:L,B21,转置表!J:J,C21,转置表!M:M,D21) -> 4804 | F21: =SUMIFS(转置表!T:T,转置表!L:L,B21,转置表!J:J,C21,转置表!M:M,D21) -> 38.916667 | G21: =E21*I21 -> 82697.917 | H21: =E21*J21 -> 93724.306 | I21: =(75000/30)*F21/E21*0.85 -> 17.214387 | J21: =(85000/30)*F21/E21*0.85 -> 19.509639 | M21: 水平井 | N21: 埕海 | O21: =N21=C21 -> TRUE | T21: 17.214387 | U21: =ROUND(T21,2) -> 17.21 | V21: 19.509639 | W21: =ROUND(V21,2) -> 19.51
A22: =ROW()-4 -> 18 | B22: 水平井 | C22: 大港页岩油 | D22: 2 | E22: =SUMIFS(转置表!O:O,转置表!L:L,B22,转置表!J:J,C22,转置表!M:M,D22) -> 18574 | F22: =SUMIFS(转置表!T:T,转置表!L:L,B22,转置表!J:J,C22,转置表!M:M,D22) -> 100.52431 | G22: =E22*I22 -> 213614.15 | H22: =E22*J22 -> 242096.04 | I22: =(75000/30)*F22/E22*0.85 -> 11.500708 | J22: =(85000/30)*F22/E22*0.85 -> 13.034136 | M22: 水平井 | N22: 大港页岩油 | O22: =N22=C22 -> TRUE | T22: 11.500708 | U22: =ROUND(T22,2) -> 11.5 | V22: 13.034136 | W22: =ROUND(V22,2) -> 13.03
A23: =ROW()-4 -> 19 | B23: 水平井 | C23: 枣园 | D23: 2 | E23: =SUMIFS(转置表!O:O,转置表!L:L,B23,转置表!J:J,C23,转置表!M:M,D23) -> 8000 | F23: =SUMIFS(转置表!T:T,转置表!L:L,B23,转置表!J:J,C23,转置表!M:M,D23) -> 83.125 | G23: =E23*I23 -> 176640.62 | H23: =E23*J23 -> 200192.71 | I23: =(75000/30)*F23/E23*0.85 -> 22.080078 | J23: =(85000/30)*F23/E23*0.85 -> 25.024089 | M23: 水平井 | N23: 枣园 | O23: =N23=C23 -> TRUE | T23: 22.080078 | U23: =ROUND(T23,2) -> 22.08 | V23: 25.024089 | W23: =ROUND(V23,2) -> 25.02
A24: =ROW()-4 -> 20 | B24: 定向井 | C24: 板桥 | D24: 3 | E24: =SUMIFS(转置表!O:O,转置表!L:L,B24,转置表!J:J,C24,转置表!M:M,D24) -> 18653 | F24: =SUMIFS(转置表!T:T,转置表!L:L,B24,转置表!J:J,C24,转置表!M:M,D24) -> 147 | G24: =E24*I24 -> 294000 | H24: =E24*J24 -> 333200 | I24: =(75000/30)*F24/E24*0.8 -> 15.76154 | J24: =(85000/30)*F24/E24*0.8 -> 17.863078 | M24: 定向井 | N24: 板桥 | O24: =N24=C24 -> TRUE | T24: 15.76154 | U24: =ROUND(T24,2) -> 15.76 | V24: 17.863078 | W24: =ROUND(V24,2) -> 17.86
A25: =ROW()-4 -> 21 | B25: 定向井 | C25: 埕海（＜4000米） | D25: 3 | E25: =SUMIFS(转置表!O:O,转置表!L:L,B25,转置表!J:J,C25,转置表!M:M,D25) -> 7594 | F25: =SUMIFS(转置表!T:T,转置表!L:L,B25,转置表!J:J,C25,转置表!M:M,D25) -> 42.9375 | G25: =E25*I25 -> 85875 | H25: =E25*J25 -> 97325 | I25: =(75000/30)*F25/E25*0.8 -> 11.30827 | J25: =(85000/30)*F25/E25*0.8 -> 12.816039 | M25: 定向井 | N25: 埕海 | O25: =N25=C25 -> FALSE | T25: 11.30827 | U25: =ROUND(T25,2) -> 11.31 | V25: 12.816039 | W25: =ROUND(V25,2) -> 12.82
A26: =ROW()-4 -> 22 | B26: 定向井 | C26: 埕海（≥4000米） | D26: 3 | E26: =SUMIFS(转置表!O:O,转置表!L:L,B26,转置表!J:J,C26,转置表!M:M,D26) -> 23072 | F26: =SUMIFS(转置表!T:T,转置表!L:L,B26,转置表!J:J,C26,转置表!M:M,D26) -> 153.79167 | G26: =E26*I26 -> 307583.33 | H26: =E26*J26 -> 348594.44 | I26: =(75000/30)*F26/E26*0.8 -> 13.331455 | J26: =(85000/30)*F26/E26*0.8 -> 15.108983 | M26: 定向井 | N26: 埕海 | O26: =N26=C26 -> FALSE | T26: 13.331455 | U26: =ROUND(T26,2) -> 13.33 | V26: 15.108983 | W26: =ROUND(V26,2) -> 15.11
A27: =ROW()-4 -> 23 | B27: 定向井 | C27: 大港页岩油 | D27: 3 | E27: =SUMIFS(转置表!O:O,转置表!L:L,B27,转置表!J:J,C27,转置表!M:M,D27) -> 3732 | F27: =SUMIFS(转置表!T:T,转置表!L:L,B27,转置表!J:J,C27,转置表!M:M,D27) -> 39 | G27: =E27*I27 -> 78000 | H27: =E27*J27 -> 88400 | I27: =(75000/30)*F27/E27*0.8 -> 20.900322 | J27: =(85000/30)*F27/E27*0.8 -> 23.687031 | M27: 定向井 | N27: 大港页岩油 | O27: =N27=C27 -> TRUE | T27: 20.900322 | U27: =ROUND(T27,2) -> 20.9 | V27: 23.687031 | W27: =ROUND(V27,2) -> 23.69
A28: =ROW()-4 -> 24 | B28: 定向井 | C28: 港东 | D28: 3 | E28: =SUMIFS(转置表!O:O,转置表!L:L,B28,转置表!J:J,C28,转置表!M:M,D28) -> 8427 | F28: =SUMIFS(转置表!T:T,转置表!L:L,B28,转置表!J:J,C28,转置表!M:M,D28) -> 113.08333 | G28: =E28*I28 -> 226166.67 | H28: =E28*J28 -> 256322.22 | I28: =(75000/30)*F28/E28*0.8 -> 26.838337 | J28: =(85000/30)*F28/E28*0.8 -> 30.416782 | M28: 定向井 | N28: 港东 | O28: =N28=C28 -> TRUE | T28: 26.838337 | U28: =ROUND(T28,2) -> 26.84 | V28: 30.416782 | W28: =ROUND(V28,2) -> 30.42
A29: =ROW()-4 -> 25 | B29: 定向井 | C29: 歧口 | D29: 3 | E29: =SUMIFS(转置表!O:O,转置表!L:L,B29,转置表!J:J,C29,转置表!M:M,D29) -> 10314 | F29: =SUMIFS(转置表!T:T,转置表!L:L,B29,转置表!J:J,C29,转置表!M:M,D29) -> 126 | G29: =E29*I29 -> 252000 | H29: =E29*J29 -> 285600 | I29: =(75000/30)*F29/E29*0.8 -> 24.43281 | J29: =(85000/30)*F29/E29*0.8 -> 27.690518 | M29: 定向井 | N29: 歧口 | O29: =N29=C29 -> TRUE | T29: 24.43281 | U29: =ROUND(T29,2) -> 24.43 | V29: 27.690518 | W29: =ROUND(V29,2) -> 27.69
A30: =ROW()-4 -> 26 | B30: 定向井 | C30: 唐东（开发井） | D30: 3 | E30: =SUMIFS(转置表!O:O,转置表!L:L,B30,转置表!J:J,C30,转置表!M:M,D30) -> 30995 | F30: =SUMIFS(转置表!T:T,转置表!L:L,B30,转置表!J:J,C30,转置表!M:M,D30) -> 201.08333 | G30: =E30*I30 -> 402166.67 | H30: =E30*J30 -> 455788.89 | I30: =(75000/30)*F30/E30*0.8 -> 12.975211 | J30: =(85000/30)*F30/E30*0.8 -> 14.705239 | T30: 12.513276 | U30: =ROUND(T30,2) -> 12.51 | V30: 14.181713 | W30: =ROUND(V30,2) -> 14.18
A31: =ROW()-4 -> 27 | B31: 定向井 | C31: 唐东（探评井） | D31: 3 | E31: =SUMIFS(转置表!O:O,转置表!L:L,B31,转置表!J:J,C31,转置表!M:M,D31) -> 27892 | F31: =SUMIFS(转置表!T:T,转置表!L:L,B31,转置表!J:J,C31,转置表!M:M,D31) -> 222.89583 | G31: =E31*I31 -> 445791.67 | H31: =E31*J31 -> 505230.56 | I31: =(75000/30)*F31/E31*0.8 -> 15.982779 | J31: =(85000/30)*F31/E31*0.8 -> 18.113816 | M31: 定向井 | N31: 唐东 | O31: =N31=C31 -> FALSE | T31: 15.187169 | U31: =ROUND(T31,2) -> 15.19 | V31: 17.212125 | W31: =ROUND(V31,2) -> 17.21
A32: =ROW()-4 -> 28 | B32: 定向井 | C32: 新华 | D32: 3 | E32: =SUMIFS(转置表!O:O,转置表!L:L,B32,转置表!J:J,C32,转置表!M:M,D32) -> 42074 | F32: =SUMIFS(转置表!T:T,转置表!L:L,B32,转置表!J:J,C32,转置表!M:M,D32) -> 377.7325 | G32: =E32*I32 -> 755465 | H32: =E32*J32 -> 856193.67 | I32: =(75000/30)*F32/E32*0.8 -> 17.955626 | J32: =(85000/30)*F32/E32*0.8 -> 20.349709 | M32: 定向井 | N32: 新华 | O32: =N32=C32 -> TRUE | T32: 16.489474 | U32: =ROUND(T32,2) -> 16.49 | V32: 18.68807 | W32: =ROUND(V32,2) -> 18.69
A33: =ROW()-4 -> 29 | B33: 水平井 | C33: 板桥 | D33: 3 | E33: =SUMIFS(转置表!O:O,转置表!L:L,B33,转置表!J:J,C33,转置表!M:M,D33) -> 0 | F33: =SUMIFS(转置表!T:T,转置表!L:L,B33,转置表!J:J,C33,转置表!M:M,D33) -> 0 | G33: =E33*I33 -> #DIV/0! | H33: =E33*J33 -> #DIV/0! | I33: =(75000/30)*F33/E33*0.8 -> #DIV/0! | J33: =(85000/30)*F33/E33*0.8 -> #DIV/0! | M33: 水平井 | N33: 板桥 | O33: =N33=C33 -> TRUE | T33: #DIV/0! | U33: =ROUND(T33,2) -> #DIV/0! | V33: #DIV/0! | W33: =ROUND(V33,2) -> #DIV/0!
A34: =ROW()-4 -> 30 | B34: 水平井 | C34: 埕海 | D34: 3 | E34: =SUMIFS(转置表!O:O,转置表!L:L,B34,转置表!J:J,C34,转置表!M:M,D34) -> 8218 | F34: =SUMIFS(转置表!T:T,转置表!L:L,B34,转置表!J:J,C34,转置表!M:M,D34) -> 62 | G34: =E34*I34 -> 124000 | H34: =E34*J34 -> 140533.33 | I34: =(75000/30)*F34/E34*0.8 -> 15.088829 | J34: =(85000/30)*F34/E34*0.8 -> 17.100673 | M34: 水平井 | N34: 埕海 | O34: =N34=C34 -> TRUE | T34: 15.088829 | U34: =ROUND(T34,2) -> 15.09 | V34: 17.100673 | W34: =ROUND(V34,2) -> 17.1
A35: =ROW()-4 -> 31 | B35: 水平井 | C35: 大港页岩油 | D35: 3 | E35: =SUMIFS(转置表!O:O,转置表!L:L,B35,转置表!J:J,C35,转置表!M:M,D35) -> 43535 | F35: =SUMIFS(转置表!T:T,转置表!L:L,B35,转置表!J:J,C35,转置表!M:M,D35) -> 389 | G35: =E35*I35 -> 778000 | H35: =E35*J35 -> 881733.33 | I35: =(75000/30)*F35/E35*0.8 -> 17.870679 | J35: =(85000/30)*F35/E35*0.8 -> 20.253436 | K35: 华页1、官页5-5-1 | M35: 水平井 | N35: 大港页岩油 | O35: =N35=C35 -> TRUE | T35: 17.870679 | U35: =ROUND(T35,2) -> 17.87 | V35: 20.253436 | W35: =ROUND(V35,2) -> 20.25
A36: =ROW()-4 -> 32 | B36: 水平井 | C36: 唐东 | D36: 3 | E36: =SUMIFS(转置表!O:O,转置表!L:L,B36,转置表!J:J,C36,转置表!M:M,D36) -> 5842 | F36: =SUMIFS(转置表!T:T,转置表!L:L,B36,转置表!J:J,C36,转置表!M:M,D36) -> 46.71 | G36: =E36*I36 -> 93420 | H36: =E36*J36 -> 105876 | I36: =(75000/30)*F36/E36*0.8 -> 15.991099 | J36: =(85000/30)*F36/E36*0.8 -> 18.123245 | M36: 水平井 | N36: 唐东 | O36: =N36=C36 -> TRUE | T36: 15.991099 | U36: =ROUND(T36,2) -> 15.99 | V36: 18.123245 | W36: =ROUND(V36,2) -> 18.12
A37: =ROW()-4 -> 33 | B37: 定向井 | C37: 板桥 | D37: 4 | E37: =SUMIFS(转置表!O:O,转置表!L:L,B37,转置表!J:J,C37,转置表!M:M,D37) -> 14474 | F37: =SUMIFS(转置表!T:T,转置表!L:L,B37,转置表!J:J,C37,转置表!M:M,D37) -> 152.77083 | G37: =E37*I37 -> 305541.67 | H37: =E37*J37 -> 346280.56 | I37: =(75000/30)*F37/E37*0.8 -> 21.109691 | J37: =(85000/30)*F37/E37*0.8 -> 23.924316 | M37: 定向井 | N37: 板桥 | O37: =N37=C37 -> TRUE | T37: 21.109691 | U37: =ROUND(T37,2) -> 21.11 | V37: 23.924316 | W37: =ROUND(V37,2) -> 23.92
B38: 定向井 | C38: 常探1 | D38: 3 | E38: 6082 | F38: 52.75 | I38: =(75000/30)*F38/E38*0.8 -> 17.346268 | J38: =(85000/30)*F38/E38*0.8 -> 19.659103
B39: 定向井 | C39: 滨188X1 | D39: 3 | E39: 5220 | F39: 53.5 | I39: =(75000/30)*F39/E39*0.8 -> 20.498084 | J39: =(85000/30)*F39/E39*0.8 -> 23.231162
B40: 定向井 | C40: 孔101-9 | D40: 2 | E40: 1761 | F40: 10 | I40: =(75000/30)*F40/E40*0.8 -> 11.357183 | J40: =(85000/30)*F40/E40*0.8 -> 12.871475
...

Sheet 纯柴油+转化柴油定额 (2)
A1: 附件1-8
A2: 大港油区柴油定额 | M2: 实际 | O2: 预算
G3: 单位：元/米 | M3: 50J | N3: 70D | O3: 50J | P3: 70D
A4: 序号 | B4: 井型 | C4: 区块 | D4: 开次 | E4: 平均井深 | F4: 平均柴油费用 | G4: 米进尺费用 | H4: 备注 | J4: 井型 | K4: 区块 | L4: 开次 | M4: 米进尺费用 | N4: 米进尺费用 | O4: 米进尺费用 | P4: 米进尺费用
A5: 1 | B5: 定向井 | C5: 板桥 | D5: 2 | E5: 3238.6875 | F5: 811397.07 | G5: =F5/E5 -> 250.53268 | J5: 定向井 | K5: 板桥 | L5: 2 | M5: =VLOOKUP(C$5:C$17,#REF!,5,FALSE) -> #REF! | N5: 177.97633 | O5: 209.79978 | P5: 174.7544
A6: 2 | B6: 定向井 | C6: 港东 | D6: 2 | E6: 1917.5 | F6: 251792.16 | G6: =F6/E6 -> 131.31273 | J6: 定向井 | K6: 港东 | L6: 2 | M6: =VLOOKUP(C$5:C$17,#REF!,5,FALSE) -> #REF! | N6: 78.841785 | O6: 119.63445 | P6: 112.38847
A7: 3 | B7: 定向井 | C7: 港西 | D7: 2 | E7: 1516.625 | F7: 268978.12 | G7: =F7/E7 -> 177.35309 | J7: 定向井 | K7: 港西 | L7: 2 | M7: =VLOOKUP(C$5:C$17,#REF!,5,FALSE) -> #REF! | O7: 161.68713
A8: 4 | B8: 定向井 | C8: 港中 | D8: 2 | E8: 2748.5 | F8: 433459 | G8: =F8/E8 -> 157.70748 | J8: 定向井 | K8: 港中 | L8: 2 | M8: =VLOOKUP(C$5:C$17,#REF!,5,FALSE) -> #REF! | O8: 125.71221
A9: 5 | B9: 定向井 | C9: 孔店 | D9: 2 | E9: 1785 | F9: 312767 | G9: =F9/E9 -> 175.21961 | J9: 定向井 | K9: 孔店 | L9: 2 | M9: =VLOOKUP(C$5:C$17,#REF!,5,FALSE) -> #REF! | O9: 152.94118
A10: 6 | B10: 定向井 | C10: 扣村 | D10: 2 | E10: 3026 | F10: 999531 | G10: =F10/E10 -> 330.31428 | J10: 定向井 | K10: 扣村 | L10: 2 | M10: =VLOOKUP(C$5:C$17,#REF!,5,FALSE) -> #REF! | O10: 290.54858
A11: 7 | B11: 定向井 | C11: 泰安 | D11: 2 | E11: 1346 | F11: 312602.51 | G11: =F11/E11 -> 232.24555 | J11: 定向井 | K11: 泰安 | L11: 2 | M11: =VLOOKUP(C$5:C$17,#REF!,5,FALSE) -> #REF! | O11: 284.57652
A12: 8 | B12: 定向井 | C12: 唐家河 | D12: 2 | E12: 3321 | F12: 358453.09 | G12: =F12/E12 -> 107.93529 | J12: 定向井 | K12: 唐家河 | L12: 2 | N12: 111.66366 | P12: 117.93135
A13: 9 | B13: 定向井 | C13: 王官屯 | D13: 2 | E13: 2859 | F13: 559907.9 | G13: =F13/E13 -> 195.84047 | J13: 定向井 | K13: 王官屯 | L13: 2 | M13: =VLOOKUP(C$5:C$17,#REF!,5,FALSE) -> #REF! | O13: 118.60091
A14: 10 | B14: 定向井 | C14: 王徐庄 | D14: 2 | E14: 2468 | F14: 411422.21 | G14: =F14/E14 -> 166.70268 | J14: 定向井 | K14: 王徐庄 | L14: 2 | M14: =VLOOKUP(C$5:C$17,#REF!,5,FALSE) -> #REF! | O14: 110.87115
A15: 11 | B15: 定向井 | C15: 羊二庄 | D15: 2 | E15: 2201 | F15: 311229.61 | G15: =F15/E15 -> 141.40373 | J15: 定向井 | K15: 羊二庄 | L15: 2 | M15: =VLOOKUP(C$5:C$17,#REF!,5,FALSE) -> #REF! | O15: 125.08405
A16: 12 | B16: 定向井 | C16: 羊三木 | D16: 2 | E16: 2775 | F16: 514657 | G16: =F16/E16 -> 185.46198 | J16: 定向井 | K16: 羊三木 | L16: 2 | M16: =VLOOKUP(C$5:C$17,#REF!,5,FALSE) -> #REF! | O16: 119.13874
